<?xml version="1.0" encoding="utf-8"?>
<!-- =================================================================================== -->
<!-- |    This document was autogenerated by xacro from vision60_gazebo.urdf.xacro     | -->
<!-- |    EDITING THIS FILE BY HAND IS NOT RECOMMENDED                                 | -->
<!-- =================================================================================== -->
<robot name="vision60">
  <!-- Define materials -->
  <material name="gray">
    <color rgba="0.5 0.5 0.5 1.0"/>
  </material>
  <material name="darkgray">
    <color rgba="0.3 0.3 0.3 1.0"/>
  </material>
  <material name="blue">
    <color rgba="0 0 0.8 1"/>
  </material>
  <material name="black">
    <color rgba="0 0 0 1"/>
  </material>
  <material name="purple">
    <color rgba="0.5 0.0 0.5 1.0"/>
  </material>
  <material name="red">
    <color rgba="0.8 0.0 0.2 1.0"/>
  </material>
  <!-- Body -->
  <link name="body">
    <visual>
      <origin rpy="0 0 0" xyz="0 0 -0.1"/>
      <geometry>
        <mesh filename="package://ghost_description/meshes/Vision60_V3/Frame.STL" scale="1 1 1"/>
      </geometry>
      <material name="gray"/>
    </visual>
    <inertial>
      <mass value="17.9"/>
      <inertia ixx="0.0986" ixy="0" ixz="0" iyy="0.8105" iyz="0" izz="0.8369"/>
    </inertial>
    <!-- Just copy geometry for collision -->
    <collision>
      <origin rpy="0 0 0" xyz="0 0 0"/>
      <geometry>
        <box size="0.83 0.25 0.19"/>
      </geometry>
    </collision>
  </link>
  <gazebo reference="body">
    <material>Gazebo/DarkGray</material>
  </gazebo>
  <!-- Traking frame comes from the realsesne _pose_frame which will share the link with realsense_link
                    (parent) d435i_link -> front_sensor_head -> extrinsics_offset_link -> body (childeren) -->
  <!-- Define front sensor head-->
  <link name="front_sensor_head_link"/>
  <!--zed center -->
  <link name="d435i_link"/>
  <link name="d435i_optical_link"/>
  <joint name="fwd_camera_link_to_zed_center" type="fixed">
    <parent link="front_sensor_head_link"/>
    <child link="d435i_link"/>
    <origin rpy="0 0 0" xyz="-0.031 0.0 0.0456"/>
    <axis xyz="1 0 0"/>
  </joint>
  <joint name="pre_opt_to_d435i_link" type="fixed">
    <parent link="d435i_link"/>
    <child link="d435i_optical_link"/>
    <origin rpy="-1.5707963267948966 0 -1.5707963267948966" xyz="0 0 0"/>
    <axis xyz="1 0 0"/>
  </joint>
  <!--forward left tof  link-->
  <link name="left_tof_optical_link"/>
  <link name="left_tof_link"/>
  <joint name="front_sensor_head_to_left_tof_link" type="fixed">
    <parent link="front_sensor_head_link"/>
    <child link="left_tof_link"/>
    <origin rpy="0 0.5235 -0.349" xyz="0.01493 0.033445  -0.00212"/>
    <axis xyz="1 0 0"/>
  </joint>
  <joint name="pre_opt_to_left_tof_link" type="fixed">
    <parent link="left_tof_link"/>
    <child link="left_tof_optical_link"/>
    <origin rpy="-1.5707963267948966 0 -1.5707963267948966" xyz="0 0 0"/>
    <axis xyz="1 0 0"/>
  </joint>
  <!--forward right tof link-->
  <link name="right_tof_link"/>
  <joint name="fwd_left_tof_link_to_right_tof_link" type="fixed">
    <parent link="front_sensor_head_link"/>
    <child link="right_tof_link"/>
    <!--<origin rpy="-0.34 0.5735 -0.13" xyz="0.01961 0.01132 0.06242"/>-->
    <!--            <origin rpy="-0.418 0.557 -0.123" xyz="0.017 0.012 0.067"/>-->
    <origin rpy="0 0.5235 0.349" xyz="0.01493 -0.033445  -0.00212"/>
    <axis xyz="0 0 1"/>
  </joint>
  <link name="right_tof_optical_link"/>
  <joint name="pre_opt_to_right_tof_link" type="fixed">
    <parent link="right_tof_link"/>
    <child link="right_tof_optical_link"/>
    <origin rpy="-1.5707963267948966 0 -1.5707963267948966" xyz="0 0 0"/>
    <axis xyz="1 0 0"/>
  </joint>
  <!--  Need to connect body to sensorhead  -->
  <joint name="body_to_sensorhead" type="fixed">
    <parent link="body"/>
    <child link="front_sensor_head_link"/>
    <origin rpy="0 0 0" xyz="0.485 0.0 0.0"/>
    <axis xyz="1 0 0"/>
  </joint>
  <!--    Side Right_tof    -->
  <link name="s_right_tof_link"/>
  <link name="s_right_tof_optical_link"/>
  <joint name="body_to_s_right_tof" type="fixed">
    <parent link="body"/>
    <child link="s_right_tof_link"/>
    <origin rpy="3.1415 0.524 -1.57" xyz="-0.082 -0.119 0.061"/>
    <axis xyz="1 0 0"/>
  </joint>
  <joint name="s_right_tof_to_optical_link" type="fixed">
    <parent link="s_right_tof_link"/>
    <child link="s_right_tof_optical_link"/>
    <origin rpy="-1.5707963267948966 0 -1.5707963267948966" xyz="0 0 0"/>
    <axis xyz="1 0 0"/>
  </joint>
  <!--    Side Left_tof    -->
  <link name="s_left_tof_link"/>
  <link name="s_left_tof_optical_link"/>
  <joint name="body_to_s_left_tof" type="fixed">
    <parent link="body"/>
    <child link="s_left_tof_link"/>
    <origin rpy="0 0.524 1.57" xyz="-0.082 0.119 0.061"/>
    <axis xyz="1 0 0"/>
  </joint>
  <joint name="s_left_tof_to_optical_link" type="fixed">
    <parent link="s_left_tof_link"/>
    <child link="s_left_tof_optical_link"/>
    <origin rpy="-1.5707963267948966 0 -1.5707963267948966" xyz="0 0 0"/>
    <axis xyz="1 0 0"/>
  </joint>
  <!--    Rear_tof    -->
  <link name="rear_tof_link"/>
  <link name="rear_tof_optical_link"/>
  <joint name="body_to_rear_tof" type="fixed">
    <parent link="body"/>
    <child link="rear_tof_link"/>
    <origin rpy="0 0.524 3.14" xyz="-0.485 0.0 0.0"/>
    <axis xyz="1 0 0"/>
  </joint>
  <joint name="rear_tof_to_optical_link" type="fixed">
    <parent link="rear_tof_link"/>
    <child link="rear_tof_optical_link"/>
    <origin rpy="-1.5707963267948966 0 -1.5707963267948966" xyz="0 0 0"/>
    <axis xyz="1 0 0"/>
  </joint>
  <!-- this way planner can run unchanged-->
  <link name="t265_pose_frame"/>
  <joint name="body_to_t265" type="fixed">
    <parent link="body"/>
    <child link="t265_pose_frame"/>
    <origin rpy="0 0 0" xyz="0.0 0.0 0.0"/>
    <axis xyz="1 0 0"/>
  </joint>
  <!--    GPS Sensor    -->
  <gazebo>
    <plugin filename="libhector_gazebo_ros_gps.so" name="gps_controller">
      <updateRate>5</updateRate>
      <robotNamespace>/</robotNamespace>
      <bodyName>body</bodyName>
      <frameId>gps_link</frameId>
      <topicName>navsat/fix</topicName>
      <velocityTopicName>navsat/vel</velocityTopicName>
      <referenceLatitude>49.9</referenceLatitude>
      <referenceLongitude>8.9</referenceLongitude>
      <referenceHeading>0</referenceHeading>
      <referenceAltitude>0</referenceAltitude>
      <drift>0.0001 0.0001 0.0001</drift>
    </plugin>
  </gazebo>
  <!--    Magnetometer    -->
  <gazebo>
    <plugin filename="libhector_gazebo_ros_magnetic.so" name="gps_controller">
      <updateRate>5</updateRate>
      <robotNamespace>/</robotNamespace>
      <bodyName>body</bodyName>
      <magnitude>1.0</magnitude>
      <declination>0.0</declination>
      <inclination>60.0</inclination>
      <topicName>magnet/fix</topicName>
      <referenceHeading>0</referenceHeading>
      <drift>0.0001 0.0001 0.0001</drift>
    </plugin>
  </gazebo>
  <!--    IMU Sensor    -->
  <gazebo reference="body">
    <gravity>true</gravity>
    <sensor name="imu_sensor" type="imu">
      <always_on>true</always_on>
      <visualize>true</visualize>
      <plugin filename="libgazebo_ros_imu_sensor.so" name="imu_plugin">
        <robotNamespace>/</robotNamespace>
        <topicName>imu</topicName>
        <bodyName>body</bodyName>
        <updateRateHZ>500.0</updateRateHZ>
        <gaussianNoise>0.0</gaussianNoise>
        <xyzOffset>0 0 0</xyzOffset>
        <rpyOffset>0 0 0</rpyOffset>
        <frameName>body</frameName>
        <initialOrientationAsReference>true</initialOrientationAsReference>
      </plugin>
      <pose>0 0 0 0 0 0</pose>
    </sensor>
  </gazebo>
  <!--    Front SensorHead Stereo    -->
  <gazebo reference="d435i_link">
    <sensor name="front_depth" type="depth">
      <update_rate>30</update_rate>
      <camera>
        <horizontal_fov>1.1</horizontal_fov>
        <image>
          <width>640</width>
          <height>480</height>
          <format>B8G8R8</format>
        </image>
        <clip>
          <near>0.01</near>
          <far>2.5</far>
        </clip>
      </camera>
      <plugin filename="libgazebo_ros_openni_kinect.so" name="front_depth_controller">
        <baseline>0.2</baseline>
        <alwaysOn>true</alwaysOn>
        <updateRate>30</updateRate>
        <cameraName>d435i</cameraName>
        <robotNamespace>/</robotNamespace>
        <imageTopicName>d435i/color/image_raw</imageTopicName>
        <cameraInfoTopicName>d435i/color/camera_info</cameraInfoTopicName>
        <depthImageTopicName>d435i/depth/image_rect_raw</depthImageTopicName>
        <depthImageCameraInfoTopicName>d435i/depth/camera_info
                    </depthImageCameraInfoTopicName>
        <pointCloudTopicName>d435i/depth/points</pointCloudTopicName>
        <frameName>d435i_optical_link</frameName>
        <pointCloudCutoff>0.01</pointCloudCutoff>
        <pointCloudCutoffMax>2.5</pointCloudCutoffMax>
        <distortionK1>0.00000001</distortionK1>
        <distortionK2>0.00000001</distortionK2>
        <distortionK3>0.00000001</distortionK3>
        <distortionT1>0.00000001</distortionT1>
        <distortionT2>0.00000001</distortionT2>
        <CxPrime>0</CxPrime>
        <Cx>0</Cx>
        <Cy>0</Cy>
        <focalLength>0</focalLength>
        <hackBaseline>0</hackBaseline>
      </plugin>
    </sensor>
  </gazebo>
  <gazebo reference="left_tof_link">
    <sensor name="left_tof" type="depth">
      <update_rate>15</update_rate>
      <camera>
        <horizontal_fov>1.08</horizontal_fov>
        <image>
          <width>224</width>
          <height>117</height>
          <format>R8G8B8</format>
        </image>
        <clip>
          <near>0.25</near>
          <far>2.0</far>
        </clip>
      </camera>
      <plugin filename="libgazebo_ros_openni_kinect.so" name="left_tof_controller">
        <baseline>0.2</baseline>
        <alwaysOn>true</alwaysOn>
        <updateRate>15</updateRate>
        <cameraName>left_tof</cameraName>
        <robotNamespace>/</robotNamespace>
        <imageTopicName>left_tof/stream/1/color/image_rect_raw</imageTopicName>
        <cameraInfoTopicName>left_tof/stream/1/color/camera_info</cameraInfoTopicName>
        <depthImageTopicName>left_tof/stream/1/depth/image_rect_raw
                    </depthImageTopicName>
        <depthImageCameraInfoTopicName>left_tof/stream/1/depth/camera_info
                    </depthImageCameraInfoTopicName>
        <pointCloudTopicName>left_tof/stream/1/cloud</pointCloudTopicName>
        <frameName>left_tof_optical_link</frameName>
        <pointCloudCutoff>0.25</pointCloudCutoff>
        <pointCloudCutoffMax>2.0</pointCloudCutoffMax>
        <distortionK1>0.00000001</distortionK1>
        <distortionK2>0.00000001</distortionK2>
        <distortionK3>0.00000001</distortionK3>
        <distortionT1>0.00000001</distortionT1>
        <distortionT2>0.00000001</distortionT2>
        <CxPrime>0</CxPrime>
        <Cx>0</Cx>
        <Cy>0</Cy>
        <focalLength>0</focalLength>
        <hackBaseline>0</hackBaseline>
      </plugin>
    </sensor>
  </gazebo>
  <gazebo reference="right_tof_link">
    <sensor name="right_tof" type="depth">
      <update_rate>15</update_rate>
      <camera>
        <horizontal_fov>1.08</horizontal_fov>
        <image>
          <width>224</width>
          <height>117</height>
          <format>R8G8B8</format>
        </image>
        <clip>
          <near>0.25</near>
          <far>2.0</far>
        </clip>
      </camera>
      <plugin filename="libgazebo_ros_openni_kinect.so" name="right_tof_controller">
        <baseline>0.2</baseline>
        <alwaysOn>true</alwaysOn>
        <updateRate>15</updateRate>
        <cameraName>right_tof</cameraName>
        <robotNamespace>/</robotNamespace>
        <imageTopicName>right_tof/stream/1/color/image_rect_raw</imageTopicName>
        <cameraInfoTopicName>right_tof/stream/1/color/camera_info</cameraInfoTopicName>
        <depthImageTopicName>right_tof/stream/1/depth/image_rect_raw
                    </depthImageTopicName>
        <depthImageCameraInfoTopicName>right_tof/stream/1/depth/camera_info
                    </depthImageCameraInfoTopicName>
        <pointCloudTopicName>right_tof/stream/1/cloud</pointCloudTopicName>
        <frameName>right_tof_optical_link</frameName>
        <pointCloudCutoff>0.25</pointCloudCutoff>
        <pointCloudCutoffMax>2.0</pointCloudCutoffMax>
        <distortionK1>0.00000001</distortionK1>
        <distortionK2>0.00000001</distortionK2>
        <distortionK3>0.00000001</distortionK3>
        <distortionT1>0.00000001</distortionT1>
        <distortionT2>0.00000001</distortionT2>
        <CxPrime>0</CxPrime>
        <Cx>0</Cx>
        <Cy>0</Cy>
        <focalLength>0</focalLength>
        <hackBaseline>0</hackBaseline>
      </plugin>
    </sensor>
  </gazebo>
  <gazebo reference="s_right_tof_link">
    <sensor name="s_right_tof" type="depth">
      <update_rate>15</update_rate>
      <camera>
        <horizontal_fov>1.08</horizontal_fov>
        <image>
          <width>224</width>
          <height>117</height>
          <format>R8G8B8</format>
        </image>
        <clip>
          <near>0.25</near>
          <far>2.0</far>
        </clip>
      </camera>
      <plugin filename="libgazebo_ros_openni_kinect.so" name="s_right_tof_controller">
        <baseline>0.2</baseline>
        <alwaysOn>true</alwaysOn>
        <updateRate>15</updateRate>
        <cameraName>s_right_tof</cameraName>
        <robotNamespace>/</robotNamespace>
        <imageTopicName>s_right_tof/stream/1/color/image_rect_raw</imageTopicName>
        <cameraInfoTopicName>s_right_tof/stream/1/color/camera_info</cameraInfoTopicName>
        <depthImageTopicName>s_right_tof/stream/1/depth/image_rect_raw
                    </depthImageTopicName>
        <depthImageCameraInfoTopicName>s_right_tof/stream/1/depth/camera_info
                    </depthImageCameraInfoTopicName>
        <pointCloudTopicName>s_right_tof/stream/1/cloud</pointCloudTopicName>
        <frameName>s_right_tof_optical_link</frameName>
        <pointCloudCutoff>0.25</pointCloudCutoff>
        <pointCloudCutoffMax>2.0</pointCloudCutoffMax>
        <distortionK1>0.00000001</distortionK1>
        <distortionK2>0.00000001</distortionK2>
        <distortionK3>0.00000001</distortionK3>
        <distortionT1>0.00000001</distortionT1>
        <distortionT2>0.00000001</distortionT2>
        <CxPrime>0</CxPrime>
        <Cx>0</Cx>
        <Cy>0</Cy>
        <focalLength>0</focalLength>
        <hackBaseline>0</hackBaseline>
      </plugin>
    </sensor>
  </gazebo>
  <gazebo reference="s_left_tof_link">
    <sensor name="s_left_tof" type="depth">
      <update_rate>15</update_rate>
      <camera>
        <horizontal_fov>1.08</horizontal_fov>
        <image>
          <width>224</width>
          <height>117</height>
          <format>R8G8B8</format>
        </image>
        <clip>
          <near>0.25</near>
          <far>2.0</far>
        </clip>
      </camera>
      <plugin filename="libgazebo_ros_openni_kinect.so" name="s_left_tof_controller">
        <baseline>0.2</baseline>
        <alwaysOn>true</alwaysOn>
        <updateRate>15</updateRate>
        <cameraName>s_left_tof</cameraName>
        <robotNamespace>/</robotNamespace>
        <imageTopicName>s_left_tof/stream/1/color/image_rect_raw</imageTopicName>
        <cameraInfoTopicName>s_left_tof/stream/1/color/camera_info</cameraInfoTopicName>
        <depthImageTopicName>s_left_tof/stream/1/depth/image_rect_raw
                    </depthImageTopicName>
        <depthImageCameraInfoTopicName>s_left_tof/stream/1/depth/camera_info
                    </depthImageCameraInfoTopicName>
        <pointCloudTopicName>s_left_tof/stream/1/cloud</pointCloudTopicName>
        <frameName>s_left_tof_optical_link</frameName>
        <pointCloudCutoff>0.25</pointCloudCutoff>
        <pointCloudCutoffMax>2.0</pointCloudCutoffMax>
        <distortionK1>0.00000001</distortionK1>
        <distortionK2>0.00000001</distortionK2>
        <distortionK3>0.00000001</distortionK3>
        <distortionT1>0.00000001</distortionT1>
        <distortionT2>0.00000001</distortionT2>
        <CxPrime>0</CxPrime>
        <Cx>0</Cx>
        <Cy>0</Cy>
        <focalLength>0</focalLength>
        <hackBaseline>0</hackBaseline>
      </plugin>
    </sensor>
  </gazebo>
  <gazebo reference="rear_tof_link">
    <sensor name="rear_tof" type="depth">
      <update_rate>15</update_rate>
      <camera>
        <horizontal_fov>1.08</horizontal_fov>
        <image>
          <width>224</width>
          <height>117</height>
          <format>R8G8B8</format>
        </image>
        <clip>
          <near>0.25</near>
          <far>2.0</far>
        </clip>
      </camera>
      <plugin filename="libgazebo_ros_openni_kinect.so" name="rear_tof_controller">
        <baseline>0.2</baseline>
        <alwaysOn>true</alwaysOn>
        <updateRate>15</updateRate>
        <cameraName>rear_tof</cameraName>
        <robotNamespace>/</robotNamespace>
        <imageTopicName>rear_tof/stream/1/color/image_rect_raw</imageTopicName>
        <cameraInfoTopicName>rear_tof/stream/1/color/camera_info</cameraInfoTopicName>
        <depthImageTopicName>rear_tof/stream/1/depth/image_rect_raw
                    </depthImageTopicName>
        <depthImageCameraInfoTopicName>rear_tof/stream/1/depth/camera_info
                    </depthImageCameraInfoTopicName>
        <pointCloudTopicName>rear_tof/stream/1/cloud</pointCloudTopicName>
        <frameName>rear_tof_optical_link</frameName>
        <pointCloudCutoff>0.25</pointCloudCutoff>
        <pointCloudCutoffMax>2.0</pointCloudCutoffMax>
        <distortionK1>0.00000001</distortionK1>
        <distortionK2>0.00000001</distortionK2>
        <distortionK3>0.00000001</distortionK3>
        <distortionT1>0.00000001</distortionT1>
        <distortionT2>0.00000001</distortionT2>
        <CxPrime>0</CxPrime>
        <Cx>0</Cx>
        <Cy>0</Cy>
        <focalLength>0</focalLength>
        <hackBaseline>0</hackBaseline>
      </plugin>
    </sensor>
  </gazebo>
  <!-- Hip motor -->
  <link name="hip0">
    <visual>
      <origin rpy="0 -3.14159265359 0" xyz="0.05 -0.073 0"/>
      <geometry>
        <mesh filename="package://ghost_description/meshes/Vision60_V3/Hip_Pod_Assembly.stl" scale="1 1 1"/>
      </geometry>
      <material name="gray"/>
    </visual>
    <collision>
      <origin rpy="1.5707963268 0 0" xyz="-0.01 -0.005 0"/>
      <geometry>
        <box size="0.15 0.09 0.15"/>
      </geometry>
    </collision>
    <inertial>
      <mass value="1.975"/>
      <inertia ixx="0.00891458" ixy="0" ixz="0" iyy="0.0100573" iyz="0" izz="0.01533698"/>
    </inertial>
  </link>
  <gazebo reference="hip0">
    <material>Gazebo/DarkGray</material>
  </gazebo>
  <!-- Abduction joint. Joint names are: 8 9 10 11 -->
  <joint name="8" type="revolute">
    <parent link="body"/>
    <child link="hip0"/>
    <axis xyz="1 0 0"/>
    <origin xyz="0.34385 0.092865 0"/>
    <limit effort="375" lower="-0.43" upper="0.43" velocity="8.6"/>
    <dynamics damping="0.0" friction="0.0"/>
  </joint>
  <!-- Transmission elements required for Gazebo -->
  <transmission name="transmission_8">
    <type>transmission_interface/SimpleTransmission</type>
    <joint name="8">
      <hardwareInterface>hardware_interface/EffortJointInterface</hardwareInterface>
    </joint>
    <actuator name="motor_8">
      <hardwareInterface>EffortJointInterface</hardwareInterface>
      <mechanicalReduction>1</mechanicalReduction>
    </actuator>
  </transmission>
  <!-- Upper leg -->
  <link name="upper0">
    <visual>
      <origin rpy="3.14 0.1179843 0" xyz="0 0 0"/>
      <geometry>
        <mesh filename="package://ghost_description/meshes/Vision60_V3/Leg_Assembly.stl" scale="0.001 0.001 0.001"/>
      </geometry>
      <material name="gray"/>
    </visual>
    <collision>
      <origin rpy="0 0 0" xyz="-0.17 0.0 0"/>
      <geometry>
        <box size="0.34 0.055 0.075"/>
      </geometry>
    </collision>
    <inertial>
      <mass value="2.525"/>
      <inertia ixx="0.0003125" ixy="0" ixz="0" iyy="0.0040625" iyz="0" izz="0.0040625"/>
    </inertial>
  </link>
  <gazebo reference="upper0">
    <material>Gazebo/DarkGray</material>
  </gazebo>
  <!-- Hip joint. (Motor to upper leg). Joint names are: 0 2 4 6 -->
  <joint name="0" type="revolute">
    <parent link="hip0"/>
    <child link="upper0"/>
    <axis xyz="0 -1 0"/>
    <origin xyz="0 0.0975 0"/>
    <!--  rpy="0 -0.3 0" -->
    <limit effort="87.5" lower="-6.28318530718" upper="6.28318530718" velocity="30"/>
    <dynamics damping="0.0" friction="0.0"/>
  </joint>
  <!-- Transmission elements required for Gazebo -->
  <transmission name="transmission_0">
    <type>transmission_interface/SimpleTransmission</type>
    <joint name="0">
      <hardwareInterface>hardware_interface/EffortJointInterface</hardwareInterface>
    </joint>
    <actuator name="motor_0">
      <hardwareInterface>EffortJointInterface</hardwareInterface>
      <mechanicalReduction>1</mechanicalReduction>
    </actuator>
  </transmission>
  <!-- Lower leg -->
  <link name="lower0">
    <visual>
      <origin rpy="0 -0.3874631  0" xyz="0 0 0"/>
      <geometry>
        <mesh filename="package://ghost_description/meshes/Vision60_V3/Lower_Leg_Assembly.stl" scale="0.001 0.001 0.001"/>
      </geometry>
      <material name="gray"/>
    </visual>
    <collision>
      <origin rpy="0 1.5707963268 0" xyz="0.17035 0 0"/>
      <geometry>
        <cylinder length="0.3407" radius="0.02"/>
      </geometry>
    </collision>
    <inertial>
      <mass value="0.375"/>
      <inertia ixx="0.00131075" ixy="0" ixz="0" iyy="0.00131075" iyz="0" izz="0.0001"/>
    </inertial>
  </link>
  <gazebo reference="lower0">
    <material>Gazebo/DarkGray</material>
  </gazebo>
  <!-- Knee joint. Joint names are: 1 3 5 7 -->
  <joint name="1" type="revolute">
    <parent link="upper0"/>
    <child link="lower0"/>
    <axis xyz="0 1 0"/>
    <origin xyz="-0.34 0 0"/>
    <!--rpy="0 0.5 0"-->
    <limit effort="87.5" lower="0" upper="3.14159265359" velocity="30"/>
    <dynamics damping="0.0" friction="0.0"/>
  </joint>
  <!-- Transmission elements required for Gazebo -->
  <transmission name="transmission_1">
    <type>transmission_interface/SimpleTransmission</type>
    <joint name="1">
      <hardwareInterface>hardware_interface/EffortJointInterface</hardwareInterface>
    </joint>
    <actuator name="motor_1">
      <hardwareInterface>EffortJointInterface</hardwareInterface>
      <mechanicalReduction>1</mechanicalReduction>
    </actuator>
  </transmission>
  <!-- Toe -->
  <link name="toe0">
    <!--            <contact>-->
    <!--                <friction_anchor/>-->
    <!--                <stiffness value="${toeStiffness}"/>-->
    <!--                <damping value="${toeDamping}"/>-->
    <!--                <spinning_friction value="${toeSpinningFriction}"/>-->
    <!--                <lateral_friction value="${toeLateralFriction}"/>-->
    <!--            </contact>-->
    <visual>
      <origin rpy="0 0 0" xyz="0 0 0"/>
      <geometry>
        <!--                     <box size="${toeRadius}*2 ${toeRadius}*2 ${toeRadius}*2"/>-->
        <sphere radius="0.001"/>
        <!--                    <sphere radius="${toeRadius}"/>-->
      </geometry>
      <material name="darkgray"/>
    </visual>
    <collision>
      <origin rpy="0 0 0" xyz="0 0 0"/>
      <geometry>
        <!--                    <box size="${toeRadius}*2 ${toeRadius}*2 ${toeRadius}*2"/>-->
        <sphere radius="0.0325"/>
      </geometry>
      <surface>
        <friction>
          <torsional>
            <coefficient>100000.0</coefficient>
            <surface_radius>100000</surface_radius>
            <use_patch_radius>false</use_patch_radius>
          </torsional>
          <ode>
            <mu>10000</mu>
            <mu2>10000</mu2>
          </ode>
        </friction>
        <contact>
          <ode>
            <kp>300000.0</kp>
            <kd>10000.0</kd>
          </ode>
        </contact>
      </surface>
    </collision>
    <inertial>
      <mass value="0.15"/>
      <inertia ixx="0.000025" ixy="0" ixz="0" iyy="0.000025" iyz="0" izz="0.000025"/>
    </inertial>
  </link>
  <gazebo reference="toe0">
    <material>Gazebo/DarkGray</material>
    <collision>
      <surface>
        <bounce>
          <restitution_coefficient>0</restitution_coefficient>
          <threshold>1e+06</threshold>
        </bounce>
        <friction>
          <torsional>
            <coefficient>1.0</coefficient>
          </torsional>
          <ode>
            <mu>500.0</mu>
            <mu2>50000.0</mu2>
          </ode>
          <bullet>
            <rolling_friction>1.0</rolling_friction>
            <friction2>50000.0</friction2>
          </bullet>
        </friction>
        <contact>
          <bullet>
            <kp>300000.0</kp>
            <kd>10000.0</kd>
          </bullet>
          <ode>
            <kp>300000.0</kp>
            <kd>10000.0</kd>
          </ode>
        </contact>
      </surface>
    </collision>
  </gazebo>
  <joint name="jtoe0" type="fixed">
    <parent link="lower0"/>
    <child link="toe0"/>
    <origin xyz="0.3407 0 -0.0"/>
    <dynamics damping="0.0" friction="0.0"/>
  </joint>
  <!-- Hip motor -->
  <link name="hip1">
    <visual>
      <origin rpy="0 0 0" xyz="-0.05 -0.073 0"/>
      <geometry>
        <mesh filename="package://ghost_description/meshes/Vision60_V3/Hip_Pod_Assembly.stl" scale="1 1 1"/>
      </geometry>
      <material name="gray"/>
    </visual>
    <collision>
      <origin rpy="1.5707963268 0 0" xyz="0.01 -0.005 0"/>
      <geometry>
        <box size="0.15 0.09 0.15"/>
      </geometry>
    </collision>
    <inertial>
      <mass value="1.975"/>
      <inertia ixx="0.00891458" ixy="0" ixz="0" iyy="0.0100573" iyz="0" izz="0.01533698"/>
    </inertial>
  </link>
  <gazebo reference="hip1">
    <material>Gazebo/DarkGray</material>
  </gazebo>
  <!-- Abduction joint. Joint names are: 8 9 10 11 -->
  <joint name="9" type="revolute">
    <parent link="body"/>
    <child link="hip1"/>
    <axis xyz="1 0 0"/>
    <origin xyz="-0.34385 0.092865 0"/>
    <limit effort="375" lower="-0.43" upper="0.43" velocity="8.6"/>
    <dynamics damping="0.0" friction="0.0"/>
  </joint>
  <!-- Transmission elements required for Gazebo -->
  <transmission name="transmission_9">
    <type>transmission_interface/SimpleTransmission</type>
    <joint name="9">
      <hardwareInterface>hardware_interface/EffortJointInterface</hardwareInterface>
    </joint>
    <actuator name="motor_9">
      <hardwareInterface>EffortJointInterface</hardwareInterface>
      <mechanicalReduction>1</mechanicalReduction>
    </actuator>
  </transmission>
  <!-- Upper leg -->
  <link name="upper1">
    <visual>
      <origin rpy="3.14 0.1179843 0" xyz="0 0 0"/>
      <geometry>
        <mesh filename="package://ghost_description/meshes/Vision60_V3/Leg_Assembly.stl" scale="0.001 0.001 0.001"/>
      </geometry>
      <material name="gray"/>
    </visual>
    <collision>
      <origin rpy="0 0 0" xyz="-0.17 0.0 0"/>
      <geometry>
        <box size="0.34 0.055 0.075"/>
      </geometry>
    </collision>
    <inertial>
      <mass value="2.525"/>
      <inertia ixx="0.0003125" ixy="0" ixz="0" iyy="0.0040625" iyz="0" izz="0.0040625"/>
    </inertial>
  </link>
  <gazebo reference="upper1">
    <material>Gazebo/DarkGray</material>
  </gazebo>
  <!-- Hip joint. (Motor to upper leg). Joint names are: 0 2 4 6 -->
  <joint name="2" type="revolute">
    <parent link="hip1"/>
    <child link="upper1"/>
    <axis xyz="0 -1 0"/>
    <origin xyz="0 0.0975 0"/>
    <!--  rpy="0 -0.3 0" -->
    <limit effort="87.5" lower="-6.28318530718" upper="6.28318530718" velocity="30"/>
    <dynamics damping="0.0" friction="0.0"/>
  </joint>
  <!-- Transmission elements required for Gazebo -->
  <transmission name="transmission_2">
    <type>transmission_interface/SimpleTransmission</type>
    <joint name="2">
      <hardwareInterface>hardware_interface/EffortJointInterface</hardwareInterface>
    </joint>
    <actuator name="motor_2">
      <hardwareInterface>EffortJointInterface</hardwareInterface>
      <mechanicalReduction>1</mechanicalReduction>
    </actuator>
  </transmission>
  <!-- Lower leg -->
  <link name="lower1">
    <visual>
      <origin rpy="0 -0.3874631  0" xyz="0 0 0"/>
      <geometry>
        <mesh filename="package://ghost_description/meshes/Vision60_V3/Lower_Leg_Assembly.stl" scale="0.001 0.001 0.001"/>
      </geometry>
      <material name="gray"/>
    </visual>
    <collision>
      <origin rpy="0 1.5707963268 0" xyz="0.17035 0 0"/>
      <geometry>
        <cylinder length="0.3407" radius="0.02"/>
      </geometry>
    </collision>
    <inertial>
      <mass value="0.375"/>
      <inertia ixx="0.00131075" ixy="0" ixz="0" iyy="0.00131075" iyz="0" izz="0.0001"/>
    </inertial>
  </link>
  <gazebo reference="lower1">
    <material>Gazebo/DarkGray</material>
  </gazebo>
  <!-- Knee joint. Joint names are: 1 3 5 7 -->
  <joint name="3" type="revolute">
    <parent link="upper1"/>
    <child link="lower1"/>
    <axis xyz="0 1 0"/>
    <origin xyz="-0.34 0 0"/>
    <!--rpy="0 0.5 0"-->
    <limit effort="87.5" lower="0" upper="3.14159265359" velocity="30"/>
    <dynamics damping="0.0" friction="0.0"/>
  </joint>
  <!-- Transmission elements required for Gazebo -->
  <transmission name="transmission_3">
    <type>transmission_interface/SimpleTransmission</type>
    <joint name="3">
      <hardwareInterface>hardware_interface/EffortJointInterface</hardwareInterface>
    </joint>
    <actuator name="motor_3">
      <hardwareInterface>EffortJointInterface</hardwareInterface>
      <mechanicalReduction>1</mechanicalReduction>
    </actuator>
  </transmission>
  <!-- Toe -->
  <link name="toe1">
    <!--            <contact>-->
    <!--                <friction_anchor/>-->
    <!--                <stiffness value="${toeStiffness}"/>-->
    <!--                <damping value="${toeDamping}"/>-->
    <!--                <spinning_friction value="${toeSpinningFriction}"/>-->
    <!--                <lateral_friction value="${toeLateralFriction}"/>-->
    <!--            </contact>-->
    <visual>
      <origin rpy="0 0 0" xyz="0 0 0"/>
      <geometry>
        <!--                     <box size="${toeRadius}*2 ${toeRadius}*2 ${toeRadius}*2"/>-->
        <sphere radius="0.001"/>
        <!--                    <sphere radius="${toeRadius}"/>-->
      </geometry>
      <material name="darkgray"/>
    </visual>
    <collision>
      <origin rpy="0 0 0" xyz="0 0 0"/>
      <geometry>
        <!--                    <box size="${toeRadius}*2 ${toeRadius}*2 ${toeRadius}*2"/>-->
        <sphere radius="0.0325"/>
      </geometry>
      <surface>
        <friction>
          <torsional>
            <coefficient>100000.0</coefficient>
            <surface_radius>100000</surface_radius>
            <use_patch_radius>false</use_patch_radius>
          </torsional>
          <ode>
            <mu>10000</mu>
            <mu2>10000</mu2>
          </ode>
        </friction>
        <contact>
          <ode>
            <kp>300000.0</kp>
            <kd>10000.0</kd>
          </ode>
        </contact>
      </surface>
    </collision>
    <inertial>
      <mass value="0.15"/>
      <inertia ixx="0.000025" ixy="0" ixz="0" iyy="0.000025" iyz="0" izz="0.000025"/>
    </inertial>
  </link>
  <gazebo reference="toe1">
    <material>Gazebo/DarkGray</material>
    <collision>
      <surface>
        <bounce>
          <restitution_coefficient>0</restitution_coefficient>
          <threshold>1e+06</threshold>
        </bounce>
        <friction>
          <torsional>
            <coefficient>1.0</coefficient>
          </torsional>
          <ode>
            <mu>500.0</mu>
            <mu2>50000.0</mu2>
          </ode>
          <bullet>
            <rolling_friction>1.0</rolling_friction>
            <friction2>50000.0</friction2>
          </bullet>
        </friction>
        <contact>
          <bullet>
            <kp>300000.0</kp>
            <kd>10000.0</kd>
          </bullet>
          <ode>
            <kp>300000.0</kp>
            <kd>10000.0</kd>
          </ode>
        </contact>
      </surface>
    </collision>
  </gazebo>
  <joint name="jtoe1" type="fixed">
    <parent link="lower1"/>
    <child link="toe1"/>
    <origin xyz="0.3407 0 -0.0"/>
    <dynamics damping="0.0" friction="0.0"/>
  </joint>
  <!-- Hip motor -->
  <link name="hip2">
    <visual>
      <origin rpy="3.14159265359 3.14159265359 0" xyz="0.05 0 -0.05"/>
      <geometry>
        <mesh filename="package://ghost_description/meshes/Vision60_V3/Hip_Pod_Assembly_Mirrored.stl" scale="1 1 1"/>
      </geometry>
      <material name="gray"/>
    </visual>
    <collision>
      <origin rpy="1.5707963268 0 0" xyz="-0.01 0.005 0"/>
      <geometry>
        <box size="0.15 0.09 0.15"/>
      </geometry>
    </collision>
    <inertial>
      <mass value="1.975"/>
      <inertia ixx="0.00891458" ixy="0" ixz="0" iyy="0.0100573" iyz="0" izz="0.01533698"/>
    </inertial>
  </link>
  <gazebo reference="hip2">
    <material>Gazebo/DarkGray</material>
  </gazebo>
  <!-- Abduction joint. Joint names are: 8 9 10 11 -->
  <joint name="10" type="revolute">
    <parent link="body"/>
    <child link="hip2"/>
    <axis xyz="1 0 0"/>
    <origin xyz="0.34385 -0.092865 0"/>
    <limit effort="375" lower="-0.43" upper="0.43" velocity="8.6"/>
    <dynamics damping="0.0" friction="0.0"/>
  </joint>
  <!-- Transmission elements required for Gazebo -->
  <transmission name="transmission_10">
    <type>transmission_interface/SimpleTransmission</type>
    <joint name="10">
      <hardwareInterface>hardware_interface/EffortJointInterface</hardwareInterface>
    </joint>
    <actuator name="motor_10">
      <hardwareInterface>EffortJointInterface</hardwareInterface>
      <mechanicalReduction>1</mechanicalReduction>
    </actuator>
  </transmission>
  <!-- Upper leg -->
  <link name="upper2">
    <visual>
      <!-- Right-->
      <origin rpy="0 0.1179843 0" xyz="0 0 0"/>
      <geometry>
        <mesh filename="package://ghost_description/meshes/Vision60_V3/Leg_Assembly_Mirrored.stl" scale="0.001 0.001 0.001"/>
      </geometry>
      <material name="gray"/>
    </visual>
    <collision>
      <origin rpy="0 0 0" xyz="-0.17 -0.0 0"/>
      <geometry>
        <box size="0.34 0.055 0.075"/>
      </geometry>
    </collision>
    <inertial>
      <mass value="2.525"/>
      <inertia ixx="0.0003125" ixy="0" ixz="0" iyy="0.0040625" iyz="0" izz="0.0040625"/>
    </inertial>
  </link>
  <gazebo reference="upper2">
    <material>Gazebo/DarkGray</material>
  </gazebo>
  <!-- Hip joint. (Motor to upper leg). Joint names are: 0 2 4 6 -->
  <joint name="4" type="revolute">
    <parent link="hip2"/>
    <child link="upper2"/>
    <axis xyz="0 -1 0"/>
    <origin xyz="0 -0.0975 0"/>
    <!--  rpy="0 -0.3 0" -->
    <limit effort="87.5" lower="-6.28318530718" upper="6.28318530718" velocity="30"/>
    <dynamics damping="0.0" friction="0.0"/>
  </joint>
  <!-- Transmission elements required for Gazebo -->
  <transmission name="transmission_4">
    <type>transmission_interface/SimpleTransmission</type>
    <joint name="4">
      <hardwareInterface>hardware_interface/EffortJointInterface</hardwareInterface>
    </joint>
    <actuator name="motor_4">
      <hardwareInterface>EffortJointInterface</hardwareInterface>
      <mechanicalReduction>1</mechanicalReduction>
    </actuator>
  </transmission>
  <!-- Lower leg -->
  <link name="lower2">
    <visual>
      <origin rpy="0 -0.3874631  0" xyz="0 0 0"/>
      <geometry>
        <mesh filename="package://ghost_description/meshes/Vision60_V3/Lower_Leg_Assembly.stl" scale="0.001 0.001 0.001"/>
      </geometry>
      <material name="gray"/>
    </visual>
    <collision>
      <origin rpy="0 1.5707963268 0" xyz="0.17035 0 0"/>
      <geometry>
        <cylinder length="0.3407" radius="0.02"/>
      </geometry>
    </collision>
    <inertial>
      <mass value="0.375"/>
      <inertia ixx="0.00131075" ixy="0" ixz="0" iyy="0.00131075" iyz="0" izz="0.0001"/>
    </inertial>
  </link>
  <gazebo reference="lower2">
    <material>Gazebo/DarkGray</material>
  </gazebo>
  <!-- Knee joint. Joint names are: 1 3 5 7 -->
  <joint name="5" type="revolute">
    <parent link="upper2"/>
    <child link="lower2"/>
    <axis xyz="0 1 0"/>
    <origin xyz="-0.34 0 0"/>
    <!--rpy="0 0.5 0"-->
    <limit effort="87.5" lower="0" upper="3.14159265359" velocity="30"/>
    <dynamics damping="0.0" friction="0.0"/>
  </joint>
  <!-- Transmission elements required for Gazebo -->
  <transmission name="transmission_5">
    <type>transmission_interface/SimpleTransmission</type>
    <joint name="5">
      <hardwareInterface>hardware_interface/EffortJointInterface</hardwareInterface>
    </joint>
    <actuator name="motor_5">
      <hardwareInterface>EffortJointInterface</hardwareInterface>
      <mechanicalReduction>1</mechanicalReduction>
    </actuator>
  </transmission>
  <!-- Toe -->
  <link name="toe2">
    <!--            <contact>-->
    <!--                <friction_anchor/>-->
    <!--                <stiffness value="${toeStiffness}"/>-->
    <!--                <damping value="${toeDamping}"/>-->
    <!--                <spinning_friction value="${toeSpinningFriction}"/>-->
    <!--                <lateral_friction value="${toeLateralFriction}"/>-->
    <!--            </contact>-->
    <visual>
      <origin rpy="0 0 0" xyz="0 0 0"/>
      <geometry>
        <!--                     <box size="${toeRadius}*2 ${toeRadius}*2 ${toeRadius}*2"/>-->
        <sphere radius="0.001"/>
        <!--                    <sphere radius="${toeRadius}"/>-->
      </geometry>
      <material name="darkgray"/>
    </visual>
    <collision>
      <origin rpy="0 0 0" xyz="0 0 0"/>
      <geometry>
        <!--                    <box size="${toeRadius}*2 ${toeRadius}*2 ${toeRadius}*2"/>-->
        <sphere radius="0.0325"/>
      </geometry>
      <surface>
        <friction>
          <torsional>
            <coefficient>100000.0</coefficient>
            <surface_radius>100000</surface_radius>
            <use_patch_radius>false</use_patch_radius>
          </torsional>
          <ode>
            <mu>10000</mu>
            <mu2>10000</mu2>
          </ode>
        </friction>
        <contact>
          <ode>
            <kp>300000.0</kp>
            <kd>10000.0</kd>
          </ode>
        </contact>
      </surface>
    </collision>
    <inertial>
      <mass value="0.15"/>
      <inertia ixx="0.000025" ixy="0" ixz="0" iyy="0.000025" iyz="0" izz="0.000025"/>
    </inertial>
  </link>
  <gazebo reference="toe2">
    <material>Gazebo/DarkGray</material>
    <collision>
      <surface>
        <bounce>
          <restitution_coefficient>0</restitution_coefficient>
          <threshold>1e+06</threshold>
        </bounce>
        <friction>
          <torsional>
            <coefficient>1.0</coefficient>
          </torsional>
          <ode>
            <mu>500.0</mu>
            <mu2>50000.0</mu2>
          </ode>
          <bullet>
            <rolling_friction>1.0</rolling_friction>
            <friction2>50000.0</friction2>
          </bullet>
        </friction>
        <contact>
          <bullet>
            <kp>300000.0</kp>
            <kd>10000.0</kd>
          </bullet>
          <ode>
            <kp>300000.0</kp>
            <kd>10000.0</kd>
          </ode>
        </contact>
      </surface>
    </collision>
  </gazebo>
  <joint name="jtoe2" type="fixed">
    <parent link="lower2"/>
    <child link="toe2"/>
    <origin xyz="0.3407 0 -0.0"/>
    <dynamics damping="0.0" friction="0.0"/>
  </joint>
  <!-- Hip motor -->
  <link name="hip3">
    <visual>
      <origin rpy="3.14159265359 0 0" xyz="-0.05 0.0 0.05"/>
      <geometry>
        <mesh filename="package://ghost_description/meshes/Vision60_V3/Hip_Pod_Assembly_Mirrored.stl" scale="1 1 1"/>
      </geometry>
      <material name="gray"/>
    </visual>
    <collision>
      <origin rpy="1.5707963268 0 0" xyz="0.01 0.005 0"/>
      <geometry>
        <box size="0.15 0.09 0.15"/>
      </geometry>
    </collision>
    <inertial>
      <mass value="1.975"/>
      <inertia ixx="0.00891458" ixy="0" ixz="0" iyy="0.0100573" iyz="0" izz="0.01533698"/>
    </inertial>
  </link>
  <gazebo reference="hip3">
    <material>Gazebo/DarkGray</material>
  </gazebo>
  <!-- Abduction joint. Joint names are: 8 9 10 11 -->
  <joint name="11" type="revolute">
    <parent link="body"/>
    <child link="hip3"/>
    <axis xyz="1 0 0"/>
    <origin xyz="-0.34385 -0.092865 0"/>
    <limit effort="375" lower="-0.43" upper="0.43" velocity="8.6"/>
    <dynamics damping="0.0" friction="0.0"/>
  </joint>
  <!-- Transmission elements required for Gazebo -->
  <transmission name="transmission_11">
    <type>transmission_interface/SimpleTransmission</type>
    <joint name="11">
      <hardwareInterface>hardware_interface/EffortJointInterface</hardwareInterface>
    </joint>
    <actuator name="motor_11">
      <hardwareInterface>EffortJointInterface</hardwareInterface>
      <mechanicalReduction>1</mechanicalReduction>
    </actuator>
  </transmission>
  <!-- Upper leg -->
  <link name="upper3">
    <visual>
      <!-- Right-->
      <origin rpy="0 0.1179843 0" xyz="0 0 0"/>
      <geometry>
        <mesh filename="package://ghost_description/meshes/Vision60_V3/Leg_Assembly_Mirrored.stl" scale="0.001 0.001 0.001"/>
      </geometry>
      <material name="gray"/>
    </visual>
    <collision>
      <origin rpy="0 0 0" xyz="-0.17 -0.0 0"/>
      <geometry>
        <box size="0.34 0.055 0.075"/>
      </geometry>
    </collision>
    <inertial>
      <mass value="2.525"/>
      <inertia ixx="0.0003125" ixy="0" ixz="0" iyy="0.0040625" iyz="0" izz="0.0040625"/>
    </inertial>
  </link>
  <gazebo reference="upper3">
    <material>Gazebo/DarkGray</material>
  </gazebo>
  <!-- Hip joint. (Motor to upper leg). Joint names are: 0 2 4 6 -->
  <joint name="6" type="revolute">
    <parent link="hip3"/>
    <child link="upper3"/>
    <axis xyz="0 -1 0"/>
    <origin xyz="0 -0.0975 0"/>
    <!--  rpy="0 -0.3 0" -->
    <limit effort="87.5" lower="-6.28318530718" upper="6.28318530718" velocity="30"/>
    <dynamics damping="0.0" friction="0.0"/>
  </joint>
  <!-- Transmission elements required for Gazebo -->
  <transmission name="transmission_6">
    <type>transmission_interface/SimpleTransmission</type>
    <joint name="6">
      <hardwareInterface>hardware_interface/EffortJointInterface</hardwareInterface>
    </joint>
    <actuator name="motor_6">
      <hardwareInterface>EffortJointInterface</hardwareInterface>
      <mechanicalReduction>1</mechanicalReduction>
    </actuator>
  </transmission>
  <!-- Lower leg -->
  <link name="lower3">
    <visual>
      <origin rpy="0 -0.3874631  0" xyz="0 0 0"/>
      <geometry>
        <mesh filename="package://ghost_description/meshes/Vision60_V3/Lower_Leg_Assembly.stl" scale="0.001 0.001 0.001"/>
      </geometry>
      <material name="gray"/>
    </visual>
    <collision>
      <origin rpy="0 1.5707963268 0" xyz="0.17035 0 0"/>
      <geometry>
        <cylinder length="0.3407" radius="0.02"/>
      </geometry>
    </collision>
    <inertial>
      <mass value="0.375"/>
      <inertia ixx="0.00131075" ixy="0" ixz="0" iyy="0.00131075" iyz="0" izz="0.0001"/>
    </inertial>
  </link>
  <gazebo reference="lower3">
    <material>Gazebo/DarkGray</material>
  </gazebo>
  <!-- Knee joint. Joint names are: 1 3 5 7 -->
  <joint name="7" type="revolute">
    <parent link="upper3"/>
    <child link="lower3"/>
    <axis xyz="0 1 0"/>
    <origin xyz="-0.34 0 0"/>
    <!--rpy="0 0.5 0"-->
    <limit effort="87.5" lower="0" upper="3.14159265359" velocity="30"/>
    <dynamics damping="0.0" friction="0.0"/>
  </joint>
  <!-- Transmission elements required for Gazebo -->
  <transmission name="transmission_7">
    <type>transmission_interface/SimpleTransmission</type>
    <joint name="7">
      <hardwareInterface>hardware_interface/EffortJointInterface</hardwareInterface>
    </joint>
    <actuator name="motor_7">
      <hardwareInterface>EffortJointInterface</hardwareInterface>
      <mechanicalReduction>1</mechanicalReduction>
    </actuator>
  </transmission>
  <!-- Toe -->
  <link name="toe3">
    <!--            <contact>-->
    <!--                <friction_anchor/>-->
    <!--                <stiffness value="${toeStiffness}"/>-->
    <!--                <damping value="${toeDamping}"/>-->
    <!--                <spinning_friction value="${toeSpinningFriction}"/>-->
    <!--                <lateral_friction value="${toeLateralFriction}"/>-->
    <!--            </contact>-->
    <visual>
      <origin rpy="0 0 0" xyz="0 0 0"/>
      <geometry>
        <!--                     <box size="${toeRadius}*2 ${toeRadius}*2 ${toeRadius}*2"/>-->
        <sphere radius="0.001"/>
        <!--                    <sphere radius="${toeRadius}"/>-->
      </geometry>
      <material name="darkgray"/>
    </visual>
    <collision>
      <origin rpy="0 0 0" xyz="0 0 0"/>
      <geometry>
        <!--                    <box size="${toeRadius}*2 ${toeRadius}*2 ${toeRadius}*2"/>-->
        <sphere radius="0.0325"/>
      </geometry>
      <surface>
        <friction>
          <torsional>
            <coefficient>100000.0</coefficient>
            <surface_radius>100000</surface_radius>
            <use_patch_radius>false</use_patch_radius>
          </torsional>
          <ode>
            <mu>10000</mu>
            <mu2>10000</mu2>
          </ode>
        </friction>
        <contact>
          <ode>
            <kp>300000.0</kp>
            <kd>10000.0</kd>
          </ode>
        </contact>
      </surface>
    </collision>
    <inertial>
      <mass value="0.15"/>
      <inertia ixx="0.000025" ixy="0" ixz="0" iyy="0.000025" iyz="0" izz="0.000025"/>
    </inertial>
  </link>
  <gazebo reference="toe3">
    <material>Gazebo/DarkGray</material>
    <collision>
      <surface>
        <bounce>
          <restitution_coefficient>0</restitution_coefficient>
          <threshold>1e+06</threshold>
        </bounce>
        <friction>
          <torsional>
            <coefficient>1.0</coefficient>
          </torsional>
          <ode>
            <mu>500.0</mu>
            <mu2>50000.0</mu2>
          </ode>
          <bullet>
            <rolling_friction>1.0</rolling_friction>
            <friction2>50000.0</friction2>
          </bullet>
        </friction>
        <contact>
          <bullet>
            <kp>300000.0</kp>
            <kd>10000.0</kd>
          </bullet>
          <ode>
            <kp>300000.0</kp>
            <kd>10000.0</kd>
          </ode>
        </contact>
      </surface>
    </collision>
  </gazebo>
  <joint name="jtoe3" type="fixed">
    <parent link="lower3"/>
    <child link="toe3"/>
    <origin xyz="0.3407 0 -0.0"/>
    <dynamics damping="0.0" friction="0.0"/>
  </joint>
  <!-- Add ros_control plugin -->
  <gazebo>
    <plugin filename="libgazebo_ros_control.so" name="gazebo_ros_control">
      <robotNamespace>//vision60</robotNamespace>
    </plugin>
  </gazebo>
</robot>

