<?xml version="1.0" encoding="utf-8"?>
<!-- =================================================================================== -->
<!-- |    This document was autogenerated by xacro from vision60_gazebo.urdf.xacro     | -->
<!-- |    EDITING THIS FILE BY HAND IS NOT RECOMMENDED                                 | -->
<!-- =================================================================================== -->
<robot name="vision60">
  <!-- Define materials -->
  <material name="gray">
    <color rgba="0.5 0.5 0.5 1.0"/>
  </material>
  <material name="darkgray">
    <color rgba="0.3 0.3 0.3 1.0"/>
  </material>
  <material name="blue">
    <color rgba="0 0 0.8 1"/>
  </material>
  <material name="black">
    <color rgba="0 0 0 1"/>
  </material>
  <material name="purple">
    <color rgba="0.5 0.0 0.5 1.0"/>
  </material>
  <material name="red">
    <color rgba="0.8 0.0 0.2 1.0"/>
  </material>
  <!-- Body -->
  <link name="body">
    <visual>
      <origin rpy="0 0 0" xyz="0 0 0"/>
      <geometry>
        <mesh filename="package://ghost_description/meshes/Vision60_V4/V4_frame_transformed.stl" scale="1 1 1"/>
      </geometry>
      <material name="gray"/>
    </visual>
    <inertial>
      <mass value="13.6"/>
      <!--		<mass value="17.9"/>-->
      <inertia ixx="0.1" ixy="0" ixz="0" iyy="0.8" iyz="0" izz="0.8"/>
      <!--		<inertia ixx="0.0986"  ixy="0"  ixz="0" iyy="0.8105" iyz="0" izz="0.8369" />-->
    </inertial>
    <!-- Just copy geometry for collision -->
    <collision>
      <origin rpy="0 0 0" xyz="0 0 0"/>
      <geometry>
        <box size="0.83 0.245 0.16"/>
      </geometry>
    </collision>
  </link>
  <gazebo reference="body">
    <material>Gazebo/DarkGray</material>
  </gazebo>
  <!-- Traking frame comes from the realsesne _pose_frame which will share the link with realsense_link
	    (parent) t265_pose_frame -> frontsensorhead -> extrinsics_offset_link -> body (childeren) -->
  <!-- branch 1 -->
  <!--connect to reset of the body -->
  <!--    <link name="t265_rot_link"/>-->
  <!--    <joint name="t265_pose_frame_to_t265_rot" type="fixed">-->
  <!--      <parent link="t265_pose_frame"/>-->
  <!--      <child link="t265_rot_link"/>-->
  <!--      <origin xyz="0 0 0" rpy="-1.57 0 0"/> &lt;!&ndash; Need a Rolled 90&ndash;&gt; -->
  <!--      <axis xyz="1 0 0"/>-->
  <!--    </joint>-->
  <!-- Define front sensor head. This connects back to the body-->
  <link name="front_sensor_head_link"/>
  <joint name="t265_to_sensor_head" type="fixed">
    <parent link="front_sensor_head_link"/>
    <child link="t265_pose_frame"/>
    <origin rpy="1.57 0 0" xyz="-0.06 0.0 -0.0507"/>
    <!--  xyz -0.0292 0.0 -0.0507 this is not correct-->
    <axis xyz="1 0 0"/>
  </joint>
  <!-- branch 2 -->
  <!-- start here: this defines the entry point for t265 based state estimate-->
  <link name="t265_fisheye1_frame"/>
  <link name="t265_pose_frame"/>
  <joint name="t265_fisheye1_frame_to_center" type="fixed">
    <parent link="t265_pose_frame"/>
    <child link="t265_fisheye1_frame"/>
    <origin rpy="0 0 0" xyz="0.0 0.032 0.0"/>
    <axis xyz="1 0 0"/>
  </joint>
  <!-- begin branch 2 from t265_fisheye1_frame -->
  <!-- connect to the rest of the sensors -->
  <link name="t265_fisheye1_optical_frame"/>
  <joint name="t265_left_frame_to_t265_left_optical" type="fixed">
    <parent link="t265_fisheye1_frame"/>
    <child link="t265_fisheye1_optical_frame"/>
    <origin rpy="-1.571 0 -1.571" xyz="0.0 0.0 0.0"/>
    <axis xyz="1 0 0 "/>
  </joint>
  <!-- Left PMD -->
  <link name="left_tof_optical_link"/>
  <joint name="t265_left_optical_link_to_left_tof_optical_frame" type="fixed">
    <parent link="t265_fisheye1_optical_frame"/>
    <child link="left_tof_optical_link"/>
    <origin rpy="0.5126 0.5579 -0.0007" xyz="0.0348 0.0941 0.0014"/>
    <axis xyz="0 0 1"/>
  </joint>
  <link name="left_tof_link"/>
  <joint name="left_tof_parent_to_sensor" type="fixed">
    <parent link="left_tof_optical_link"/>
    <child link="left_tof_link"/>
    <origin rpy="1.5708 -1.5708 0 " xyz="0 0 0"/>
    <axis xyz="1 0 0"/>
  </joint>
  <!-- Righ PMD -->
  <link name="right_tof_optical_link"/>
  <joint name="left_tof_optical_frame_to_right_tof_optical_frame" type="fixed">
    <parent link="left_tof_optical_link"/>
    <child link="right_tof_optical_link"/>
    <origin rpy="-1.0020 -0.0021 -0.0055" xyz="0.0012 -0.1654 0.0910"/>
    <axis xyz="0 0 1"/>
  </joint>
  <link name="right_tof_link"/>
  <joint name="right_tof_parent_to_sensor" type="fixed">
    <parent link="right_tof_optical_link"/>
    <child link="right_tof_link"/>
    <origin rpy="1.5708 -1.5708 0" xyz="0 0 0"/>
    <axis xyz="1 0 0"/>
  </joint>
  <!--  Need to connect body to sensorhead  -->
  <joint name="body_to_sensorhead" type="fixed">
    <parent link="body"/>
    <child link="front_sensor_head_link"/>
    <origin rpy="0 0 0" xyz="0.485 0.0 0.0"/>
    <axis xyz="1 0 0"/>
  </joint>
  <!--    Side Right_tof    -->
  <link name="s_right_tof_link"/>
  <link name="s_right_tof_optical_link"/>
  <joint name="body_to_s_right_tof" type="fixed">
    <parent link="body"/>
    <child link="s_right_tof_link"/>
    <origin rpy="3.1415 0.524 -1.57" xyz="-0.082 -0.119 0.061"/>
    <axis xyz="1 0 0"/>
  </joint>
  <joint name="s_right_tof_to_optical_link" type="fixed">
    <parent link="s_right_tof_link"/>
    <child link="s_right_tof_optical_link"/>
    <origin rpy="-1.5707963267948966 0 -1.5707963267948966" xyz="0 0 0"/>
    <axis xyz="1 0 0"/>
  </joint>
  <!--    Side Left_tof    -->
  <link name="s_left_tof_link"/>
  <link name="s_left_tof_optical_link"/>
  <joint name="body_to_s_left_tof" type="fixed">
    <parent link="body"/>
    <child link="s_left_tof_link"/>
    <origin rpy="0 0.524 1.57" xyz="-0.082 0.119 0.061"/>
    <axis xyz="1 0 0"/>
  </joint>
  <joint name="s_left_tof_to_optical_link" type="fixed">
    <parent link="s_left_tof_link"/>
    <child link="s_left_tof_optical_link"/>
    <origin rpy="-1.5707963267948966 0 -1.5707963267948966" xyz="0 0 0"/>
    <axis xyz="1 0 0"/>
  </joint>
  <!--    Rear_tof    -->
  <link name="rear_tof_link"/>
  <link name="rear_tof_optical_link"/>
  <joint name="body_to_rear_tof" type="fixed">
    <parent link="body"/>
    <child link="rear_tof_link"/>
    <origin rpy="0 0.524 3.14" xyz="-0.485 0.0 0.0"/>
    <axis xyz="1 0 0"/>
  </joint>
  <joint name="rear_tof_to_optical_link" type="fixed">
    <parent link="rear_tof_link"/>
    <child link="rear_tof_optical_link"/>
    <origin rpy="-1.5707963267948966 0 -1.5707963267948966" xyz="0 0 0"/>
    <axis xyz="1 0 0"/>
  </joint>
  <!--    GPS Sensor    -->
  <gazebo>
    <plugin filename="libhector_gazebo_ros_gps.so" name="gps_controller">
      <updateRate>5</updateRate>
      <robotNamespace>/</robotNamespace>
      <bodyName>body</bodyName>
      <frameId>gps_link</frameId>
      <topicName>navsat/fix</topicName>
      <velocityTopicName>navsat/vel</velocityTopicName>
      <referenceLatitude>49.9</referenceLatitude>
      <referenceLongitude>8.9</referenceLongitude>
      <referenceHeading>0</referenceHeading>
      <referenceAltitude>0</referenceAltitude>
      <drift>0.0001 0.0001 0.0001</drift>
    </plugin>
  </gazebo>
  <!--    IMU Sensor    -->
  <gazebo reference="body">
    <gravity>true</gravity>
    <sensor name="imu_sensor" type="imu">
      <always_on>true</always_on>
      <visualize>true</visualize>
      <plugin filename="libgazebo_ros_imu_sensor.so" name="imu_plugin">
        <robotNamespace>/</robotNamespace>
        <topicName>imu</topicName>
        <bodyName>body</bodyName>
        <updateRateHZ>500.0</updateRateHZ>
        <gaussianNoise>0.0</gaussianNoise>
        <xyzOffset>0 0 0</xyzOffset>
        <rpyOffset>0 0 0</rpyOffset>
        <frameName>body</frameName>
        <initialOrientationAsReference>true</initialOrientationAsReference>
      </plugin>
      <pose>0 0 0 0 0 0</pose>
    </sensor>
  </gazebo>
  <gazebo reference="left_tof_link">
    <sensor name="left_tof" type="depth">
      <update_rate>30</update_rate>
      <camera>
        <horizontal_fov>1.57</horizontal_fov>
        <image>
          <width>640</width>
          <height>480</height>
          <format>R8G8B8</format>
        </image>
        <clip>
          <near>0.25</near>
          <far>3.0</far>
        </clip>
      </camera>
      <plugin filename="libgazebo_ros_openni_kinect.so" name="left_tof_controller">
        <baseline>0.2</baseline>
        <alwaysOn>true</alwaysOn>
        <updateRate>30</updateRate>
        <cameraName>left_tof</cameraName>
        <robotNamespace>/</robotNamespace>
        <imageTopicName>left_tof/stream/1/color/image_rect_raw</imageTopicName>
        <cameraInfoTopicName>left_tof/stream/1/color/camera_info</cameraInfoTopicName>
        <depthImageTopicName>left_tof/stream/1/depth/image_rect_raw
                    </depthImageTopicName>
        <depthImageCameraInfoTopicName>left_tof/stream/1/depth/camera_info
                    </depthImageCameraInfoTopicName>
        <pointCloudTopicName>left_tof/stream/1/cloud</pointCloudTopicName>
        <frameName>left_tof_optical_link</frameName>
        <pointCloudCutoff>0.25</pointCloudCutoff>
        <pointCloudCutoffMax>3.0</pointCloudCutoffMax>
        <distortionK1>0.00000001</distortionK1>
        <distortionK2>0.00000001</distortionK2>
        <distortionK3>0.00000001</distortionK3>
        <distortionT1>0.00000001</distortionT1>
        <distortionT2>0.00000001</distortionT2>
        <CxPrime>0</CxPrime>
        <Cx>0</Cx>
        <Cy>0</Cy>
        <focalLength>0</focalLength>
        <hackBaseline>0</hackBaseline>
      </plugin>
    </sensor>
  </gazebo>
  <gazebo reference="right_tof_link">
    <sensor name="right_tof" type="depth">
      <update_rate>30</update_rate>
      <camera>
        <horizontal_fov>1.57</horizontal_fov>
        <image>
          <width>640</width>
          <height>480</height>
          <format>R8G8B8</format>
        </image>
        <clip>
          <near>0.25</near>
          <far>3.0</far>
        </clip>
      </camera>
      <plugin filename="libgazebo_ros_openni_kinect.so" name="right_tof_controller">
        <baseline>0.2</baseline>
        <alwaysOn>true</alwaysOn>
        <updateRate>30</updateRate>
        <cameraName>right_tof</cameraName>
        <robotNamespace>/</robotNamespace>
        <imageTopicName>right_tof/stream/1/color/image_rect_raw</imageTopicName>
        <cameraInfoTopicName>right_tof/stream/1/color/camera_info</cameraInfoTopicName>
        <depthImageTopicName>right_tof/stream/1/depth/image_rect_raw
                    </depthImageTopicName>
        <depthImageCameraInfoTopicName>right_tof/stream/1/depth/camera_info
                    </depthImageCameraInfoTopicName>
        <pointCloudTopicName>right_tof/stream/1/cloud</pointCloudTopicName>
        <frameName>right_tof_optical_link</frameName>
        <pointCloudCutoff>0.25</pointCloudCutoff>
        <pointCloudCutoffMax>3.0</pointCloudCutoffMax>
        <distortionK1>0.00000001</distortionK1>
        <distortionK2>0.00000001</distortionK2>
        <distortionK3>0.00000001</distortionK3>
        <distortionT1>0.00000001</distortionT1>
        <distortionT2>0.00000001</distortionT2>
        <CxPrime>0</CxPrime>
        <Cx>0</Cx>
        <Cy>0</Cy>
        <focalLength>0</focalLength>
        <hackBaseline>0</hackBaseline>
      </plugin>
    </sensor>
  </gazebo>
  <gazebo reference="s_right_tof_link">
    <sensor name="s_right_tof" type="depth">
      <update_rate>30</update_rate>
      <camera>
        <horizontal_fov>1.57</horizontal_fov>
        <image>
          <width>640</width>
          <height>480</height>
          <format>R8G8B8</format>
        </image>
        <clip>
          <near>0.25</near>
          <far>3.0</far>
        </clip>
      </camera>
      <plugin filename="libgazebo_ros_openni_kinect.so" name="s_right_tof_controller">
        <baseline>0.2</baseline>
        <alwaysOn>true</alwaysOn>
        <updateRate>30</updateRate>
        <cameraName>s_right_tof</cameraName>
        <robotNamespace>/</robotNamespace>
        <imageTopicName>s_right_tof/stream/1/color/image_rect_raw</imageTopicName>
        <cameraInfoTopicName>s_right_tof/stream/1/color/camera_info</cameraInfoTopicName>
        <depthImageTopicName>s_right_tof/stream/1/depth/image_rect_raw
                    </depthImageTopicName>
        <depthImageCameraInfoTopicName>s_right_tof/stream/1/depth/camera_info
                    </depthImageCameraInfoTopicName>
        <pointCloudTopicName>s_right_tof/stream/1/cloud</pointCloudTopicName>
        <frameName>s_right_tof_optical_link</frameName>
        <pointCloudCutoff>0.25</pointCloudCutoff>
        <pointCloudCutoffMax>3.0</pointCloudCutoffMax>
        <distortionK1>0.00000001</distortionK1>
        <distortionK2>0.00000001</distortionK2>
        <distortionK3>0.00000001</distortionK3>
        <distortionT1>0.00000001</distortionT1>
        <distortionT2>0.00000001</distortionT2>
        <CxPrime>0</CxPrime>
        <Cx>0</Cx>
        <Cy>0</Cy>
        <focalLength>0</focalLength>
        <hackBaseline>0</hackBaseline>
      </plugin>
    </sensor>
  </gazebo>
  <gazebo reference="s_left_tof_link">
    <sensor name="s_left_tof" type="depth">
      <update_rate>30</update_rate>
      <camera>
        <horizontal_fov>1.57</horizontal_fov>
        <image>
          <width>640</width>
          <height>480</height>
          <format>R8G8B8</format>
        </image>
        <clip>
          <near>0.25</near>
          <far>3.0</far>
        </clip>
      </camera>
      <plugin filename="libgazebo_ros_openni_kinect.so" name="s_left_tof_controller">
        <baseline>0.2</baseline>
        <alwaysOn>true</alwaysOn>
        <updateRate>30</updateRate>
        <cameraName>s_left_tof</cameraName>
        <robotNamespace>/</robotNamespace>
        <imageTopicName>s_left_tof/stream/1/color/image_rect_raw</imageTopicName>
        <cameraInfoTopicName>s_left_tof/stream/1/color/camera_info</cameraInfoTopicName>
        <depthImageTopicName>s_left_tof/stream/1/depth/image_rect_raw
                    </depthImageTopicName>
        <depthImageCameraInfoTopicName>s_left_tof/stream/1/depth/camera_info
                    </depthImageCameraInfoTopicName>
        <pointCloudTopicName>s_left_tof/stream/1/cloud</pointCloudTopicName>
        <frameName>s_left_tof_optical_link</frameName>
        <pointCloudCutoff>0.25</pointCloudCutoff>
        <pointCloudCutoffMax>3.0</pointCloudCutoffMax>
        <distortionK1>0.00000001</distortionK1>
        <distortionK2>0.00000001</distortionK2>
        <distortionK3>0.00000001</distortionK3>
        <distortionT1>0.00000001</distortionT1>
        <distortionT2>0.00000001</distortionT2>
        <CxPrime>0</CxPrime>
        <Cx>0</Cx>
        <Cy>0</Cy>
        <focalLength>0</focalLength>
        <hackBaseline>0</hackBaseline>
      </plugin>
    </sensor>
  </gazebo>
  <gazebo reference="rear_tof_link">
    <sensor name="rear_tof" type="depth">
      <update_rate>30</update_rate>
      <camera>
        <horizontal_fov>1.57</horizontal_fov>
        <image>
          <width>640</width>
          <height>480</height>
          <format>R8G8B8</format>
        </image>
        <clip>
          <near>0.25</near>
          <far>3.0</far>
        </clip>
      </camera>
      <plugin filename="libgazebo_ros_openni_kinect.so" name="rear_tof_controller">
        <baseline>0.2</baseline>
        <alwaysOn>true</alwaysOn>
        <updateRate>30</updateRate>
        <cameraName>rear_tof</cameraName>
        <robotNamespace>/</robotNamespace>
        <imageTopicName>rear_tof/stream/1/color/image_rect_raw</imageTopicName>
        <cameraInfoTopicName>rear_tof/stream/1/color/camera_info</cameraInfoTopicName>
        <depthImageTopicName>rear_tof/stream/1/depth/image_rect_raw
                    </depthImageTopicName>
        <depthImageCameraInfoTopicName>rear_tof/stream/1/depth/camera_info
                    </depthImageCameraInfoTopicName>
        <pointCloudTopicName>rear_tof/stream/1/cloud</pointCloudTopicName>
        <frameName>rear_tof_optical_link</frameName>
        <pointCloudCutoff>0.25</pointCloudCutoff>
        <pointCloudCutoffMax>3.0</pointCloudCutoffMax>
        <distortionK1>0.00000001</distortionK1>
        <distortionK2>0.00000001</distortionK2>
        <distortionK3>0.00000001</distortionK3>
        <distortionT1>0.00000001</distortionT1>
        <distortionT2>0.00000001</distortionT2>
        <CxPrime>0</CxPrime>
        <Cx>0</Cx>
        <Cy>0</Cy>
        <focalLength>0</focalLength>
        <hackBaseline>0</hackBaseline>
      </plugin>
    </sensor>
  </gazebo>
  <!-- Hip motor -->
  <link name="hip0">
    <visual>
      <origin rpy="0 0 0" xyz="0 0.0 0"/>
      <geometry>
        <mesh filename="package://ghost_description/meshes/Vision60_V4/V4_hip_transformed.stl" scale="1 1 1"/>
      </geometry>
      <material name="gray"/>
    </visual>
    <collision>
      <origin rpy="1.5707963268 0 0" xyz="-0.015 -0.01 0"/>
      <geometry>
        <box size="0.19 0.09 0.14"/>
      </geometry>
    </collision>
    <inertial>
      <mass value="3.1"/>
      <!--		<mass value="1.975"/>-->
      <inertia ixx="0.01" ixy="0" ixz="0" iyy="0.01" iyz="0" izz="0.015"/>
      <!--		<inertia ixx="0.00891458"  ixy="0"  ixz="0" iyy="0.0100573" iyz="0" izz="0.01533698" />-->
    </inertial>
  </link>
  <gazebo reference="hip0">
    <material>Gazebo/DarkGray</material>
  </gazebo>
  <!-- Abduction joint. Joint names are: 8 9 10 11 -->
  <joint name="8" type="revolute">
    <parent link="body"/>
    <child link="hip0"/>
    <axis xyz="1 0 0"/>
    <origin xyz="0.308 0.0955 0"/>
    <limit effort="375" lower="-0.53" upper="0.53" velocity="8.6"/>
    <dynamics damping="0.0" friction="0.0"/>
  </joint>
  <!-- Transmission elements required for Gazebo -->
  <transmission name="transmission_8">
    <type>transmission_interface/SimpleTransmission</type>
    <joint name="8">
      <hardwareInterface>hardware_interface/EffortJointInterface</hardwareInterface>
    </joint>
    <actuator name="motor_8">
      <hardwareInterface>EffortJointInterface</hardwareInterface>
      <mechanicalReduction>1</mechanicalReduction>
    </actuator>
  </transmission>
  <!-- Upper leg -->
  <link name="upper0">
    <visual>
      <origin rpy="3.14159265359 0 0" xyz="0 0 0"/>
      <geometry>
        <mesh filename="package://ghost_description/meshes/Vision60_V4/V4_Upper_leg_transformed.stl" scale="1 1 1"/>
      </geometry>
      <material name="gray"/>
    </visual>
    <collision>
      <origin rpy="0 0 0" xyz="-0.16 0.0 0"/>
      <geometry>
        <box size="0.32 0.055 0.08"/>
      </geometry>
    </collision>
    <inertial>
      <mass value="2.7"/>
      <!--		<mass value="2.525"/>-->
      <inertia ixx="0.0003" ixy="0" ixz="0" iyy="0.004" iyz="0" izz="0.004"/>
      <!--		<inertia ixx="0.0003125"  ixy="0" ixz="0" iyy="0.0040625" iyz="0" izz="0.0040625" />-->
    </inertial>
  </link>
  <gazebo reference="upper0">
    <material>Gazebo/DarkGray</material>
  </gazebo>
  <!-- Hip joint. (Motor to upper leg). Joint names are: 0 2 4 6 -->
  <joint name="0" type="revolute">
    <parent link="hip0"/>
    <child link="upper0"/>
    <axis xyz="0 -1 0"/>
    <origin xyz="0 0.0875 0"/>
    <!--  rpy="0 -0.3 0" -->
    <limit effort="87.5" lower="-6.28318530718" upper="6.28318530718" velocity="30"/>
    <dynamics damping="0.0" friction="0.0"/>
  </joint>
  <!-- Transmission elements required for Gazebo -->
  <transmission name="transmission_0">
    <type>transmission_interface/SimpleTransmission</type>
    <joint name="0">
      <hardwareInterface>hardware_interface/EffortJointInterface</hardwareInterface>
    </joint>
    <actuator name="motor_0">
      <hardwareInterface>EffortJointInterface</hardwareInterface>
      <mechanicalReduction>1</mechanicalReduction>
    </actuator>
  </transmission>
  <!-- Lower leg -->
  <link name="lower0">
    <visual>
      <origin rpy="0 0 0" xyz="0 0.02 0"/>
      <geometry>
        <mesh filename="package://ghost_description/meshes/Vision60_V4/V4_Lower_leg_transformed.stl" scale="1 1 1"/>
      </geometry>
      <material name="gray"/>
    </visual>
    <collision>
      <origin rpy="0 1.5707963268 0" xyz="0.1588 0 0"/>
      <geometry>
        <cylinder length="0.3176" radius="0.02"/>
      </geometry>
    </collision>
    <inertial>
      <mass value="0.65"/>
      <!--		<mass value="0.375"/>-->
      <inertia ixx="0.001" ixy="0" ixz="0" iyy="0.001" iyz="0" izz="0.0001"/>
      <!--		<inertia ixx="0.00131075"  ixy="0"  ixz="0" iyy="0.00131075" iyz="0" izz="0.0001" />-->
    </inertial>
  </link>
  <gazebo reference="lower0">
    <material>Gazebo/DarkGray</material>
  </gazebo>
  <!-- Knee joint. Joint names are: 1 3 5 7 -->
  <joint name="1" type="revolute">
    <parent link="upper0"/>
    <child link="lower0"/>
    <axis xyz="0 1 0"/>
    <origin xyz="-0.32 0 0"/>
    <!--rpy="0 0.5 0"-->
    <limit effort="87.5" lower="0" upper="3.14159265359" velocity="30"/>
    <dynamics damping="0.0" friction="0.0"/>
  </joint>
  <!-- Transmission elements required for Gazebo -->
  <transmission name="transmission_1">
    <type>transmission_interface/SimpleTransmission</type>
    <joint name="1">
      <hardwareInterface>hardware_interface/EffortJointInterface</hardwareInterface>
    </joint>
    <actuator name="motor_1">
      <hardwareInterface>EffortJointInterface</hardwareInterface>
      <mechanicalReduction>1</mechanicalReduction>
    </actuator>
  </transmission>
  <!-- Toe -->
  <link name="toe0">
    <!--            <contact>-->
    <!--                <friction_anchor/>-->
    <!--                <stiffness value="${toeStiffness}"/>-->
    <!--                <damping value="${toeDamping}"/>-->
    <!--                <spinning_friction value="${toeSpinningFriction}"/>-->
    <!--                <lateral_friction value="${toeLateralFriction}"/>-->
    <!--            </contact>-->
    <visual>
      <origin rpy="0 0 0" xyz="0 0 0"/>
      <geometry>
        <!--                     <box size="${toeRadius}*2 ${toeRadius}*2 ${toeRadius}*2"/>-->
        <sphere radius="0.001"/>
        <!--                    <sphere radius="${toeRadius}"/>-->
      </geometry>
      <material name="darkgray"/>
    </visual>
    <collision>
      <origin rpy="0 0 0" xyz="0 0 0"/>
      <geometry>
        <!--                    <box size="${toeRadius}*2 ${toeRadius}*2 ${toeRadius}*2"/>-->
        <sphere radius="0.0325"/>
      </geometry>
      <surface>
        <friction>
          <torsional>
            <coefficient>100000.0</coefficient>
            <surface_radius>100000</surface_radius>
            <use_patch_radius>false</use_patch_radius>
          </torsional>
          <ode>
            <mu>10000</mu>
            <mu2>10000</mu2>
          </ode>
        </friction>
        <contact>
          <ode>
            <kp>300000.0</kp>
            <kd>10000.0</kd>
          </ode>
        </contact>
      </surface>
    </collision>
    <inertial>
      <mass value="0.05"/>
      <inertia ixx="0.000025" ixy="0" ixz="0" iyy="0.000025" iyz="0" izz="0.000025"/>
      <!--		<inertia ixx="0.000025"  ixy="0"  ixz="0" iyy="0.000025" iyz="0" izz="0.000025" />-->
    </inertial>
  </link>
  <gazebo reference="toe0">
    <material>Gazebo/DarkGray</material>
    <collision>
      <surface>
        <bounce>
          <restitution_coefficient>0</restitution_coefficient>
          <threshold>1e+06</threshold>
        </bounce>
        <friction>
          <torsional>
            <coefficient>1.0</coefficient>
          </torsional>
          <ode>
            <mu>500.0</mu>
            <mu2>50000.0</mu2>
          </ode>
          <bullet>
            <rolling_friction>1.0</rolling_friction>
            <friction2>50000.0</friction2>
          </bullet>
        </friction>
        <contact>
          <bullet>
            <kp>300000.0</kp>
            <kd>10000.0</kd>
          </bullet>
          <ode>
            <kp>300000.0</kp>
            <kd>10000.0</kd>
          </ode>
        </contact>
      </surface>
    </collision>
  </gazebo>
  <joint name="jtoe0" type="fixed">
    <parent link="lower0"/>
    <child link="toe0"/>
    <origin xyz="0.3176 0 -0.0"/>
    <dynamics damping="0.0" friction="0.0"/>
  </joint>
  <!-- Hip motor -->
  <link name="hip1">
    <visual>
      <origin rpy="0 3.14159265359 0" xyz="0.0 0.0 0"/>
      <geometry>
        <mesh filename="package://ghost_description/meshes/Vision60_V4/V4_hip_transformed.stl" scale="1 1 1"/>
      </geometry>
      <material name="gray"/>
    </visual>
    <collision>
      <origin rpy="1.5707963268 0 0" xyz="0.015 -0.01 0"/>
      <geometry>
        <box size="0.19 0.09 0.14"/>
      </geometry>
    </collision>
    <inertial>
      <mass value="3.1"/>
      <!--		<mass value="1.975"/>-->
      <inertia ixx="0.01" ixy="0" ixz="0" iyy="0.01" iyz="0" izz="0.015"/>
      <!--		<inertia ixx="0.00891458"  ixy="0"  ixz="0" iyy="0.0100573" iyz="0" izz="0.01533698" />-->
    </inertial>
  </link>
  <gazebo reference="hip1">
    <material>Gazebo/DarkGray</material>
  </gazebo>
  <!-- Abduction joint. Joint names are: 8 9 10 11 -->
  <joint name="9" type="revolute">
    <parent link="body"/>
    <child link="hip1"/>
    <axis xyz="1 0 0"/>
    <origin xyz="-0.308 0.0955 0"/>
    <limit effort="375" lower="-0.53" upper="0.53" velocity="8.6"/>
    <dynamics damping="0.0" friction="0.0"/>
  </joint>
  <!-- Transmission elements required for Gazebo -->
  <transmission name="transmission_9">
    <type>transmission_interface/SimpleTransmission</type>
    <joint name="9">
      <hardwareInterface>hardware_interface/EffortJointInterface</hardwareInterface>
    </joint>
    <actuator name="motor_9">
      <hardwareInterface>EffortJointInterface</hardwareInterface>
      <mechanicalReduction>1</mechanicalReduction>
    </actuator>
  </transmission>
  <!-- Upper leg -->
  <link name="upper1">
    <visual>
      <origin rpy="3.14159265359 0 0" xyz="0 0 0"/>
      <geometry>
        <mesh filename="package://ghost_description/meshes/Vision60_V4/V4_Upper_leg_transformed.stl" scale="1 1 1"/>
      </geometry>
      <material name="gray"/>
    </visual>
    <collision>
      <origin rpy="0 0 0" xyz="-0.16 0.0 0"/>
      <geometry>
        <box size="0.32 0.055 0.08"/>
      </geometry>
    </collision>
    <inertial>
      <mass value="2.7"/>
      <!--		<mass value="2.525"/>-->
      <inertia ixx="0.0003" ixy="0" ixz="0" iyy="0.004" iyz="0" izz="0.004"/>
      <!--		<inertia ixx="0.0003125"  ixy="0" ixz="0" iyy="0.0040625" iyz="0" izz="0.0040625" />-->
    </inertial>
  </link>
  <gazebo reference="upper1">
    <material>Gazebo/DarkGray</material>
  </gazebo>
  <!-- Hip joint. (Motor to upper leg). Joint names are: 0 2 4 6 -->
  <joint name="2" type="revolute">
    <parent link="hip1"/>
    <child link="upper1"/>
    <axis xyz="0 -1 0"/>
    <origin xyz="0 0.0875 0"/>
    <!--  rpy="0 -0.3 0" -->
    <limit effort="87.5" lower="-6.28318530718" upper="6.28318530718" velocity="30"/>
    <dynamics damping="0.0" friction="0.0"/>
  </joint>
  <!-- Transmission elements required for Gazebo -->
  <transmission name="transmission_2">
    <type>transmission_interface/SimpleTransmission</type>
    <joint name="2">
      <hardwareInterface>hardware_interface/EffortJointInterface</hardwareInterface>
    </joint>
    <actuator name="motor_2">
      <hardwareInterface>EffortJointInterface</hardwareInterface>
      <mechanicalReduction>1</mechanicalReduction>
    </actuator>
  </transmission>
  <!-- Lower leg -->
  <link name="lower1">
    <visual>
      <origin rpy="0 0 0" xyz="0 0.02 0"/>
      <geometry>
        <mesh filename="package://ghost_description/meshes/Vision60_V4/V4_Lower_leg_transformed.stl" scale="1 1 1"/>
      </geometry>
      <material name="gray"/>
    </visual>
    <collision>
      <origin rpy="0 1.5707963268 0" xyz="0.1588 0 0"/>
      <geometry>
        <cylinder length="0.3176" radius="0.02"/>
      </geometry>
    </collision>
    <inertial>
      <mass value="0.65"/>
      <!--		<mass value="0.375"/>-->
      <inertia ixx="0.001" ixy="0" ixz="0" iyy="0.001" iyz="0" izz="0.0001"/>
      <!--		<inertia ixx="0.00131075"  ixy="0"  ixz="0" iyy="0.00131075" iyz="0" izz="0.0001" />-->
    </inertial>
  </link>
  <gazebo reference="lower1">
    <material>Gazebo/DarkGray</material>
  </gazebo>
  <!-- Knee joint. Joint names are: 1 3 5 7 -->
  <joint name="3" type="revolute">
    <parent link="upper1"/>
    <child link="lower1"/>
    <axis xyz="0 1 0"/>
    <origin xyz="-0.32 0 0"/>
    <!--rpy="0 0.5 0"-->
    <limit effort="87.5" lower="0" upper="3.14159265359" velocity="30"/>
    <dynamics damping="0.0" friction="0.0"/>
  </joint>
  <!-- Transmission elements required for Gazebo -->
  <transmission name="transmission_3">
    <type>transmission_interface/SimpleTransmission</type>
    <joint name="3">
      <hardwareInterface>hardware_interface/EffortJointInterface</hardwareInterface>
    </joint>
    <actuator name="motor_3">
      <hardwareInterface>EffortJointInterface</hardwareInterface>
      <mechanicalReduction>1</mechanicalReduction>
    </actuator>
  </transmission>
  <!-- Toe -->
  <link name="toe1">
    <!--            <contact>-->
    <!--                <friction_anchor/>-->
    <!--                <stiffness value="${toeStiffness}"/>-->
    <!--                <damping value="${toeDamping}"/>-->
    <!--                <spinning_friction value="${toeSpinningFriction}"/>-->
    <!--                <lateral_friction value="${toeLateralFriction}"/>-->
    <!--            </contact>-->
    <visual>
      <origin rpy="0 0 0" xyz="0 0 0"/>
      <geometry>
        <!--                     <box size="${toeRadius}*2 ${toeRadius}*2 ${toeRadius}*2"/>-->
        <sphere radius="0.001"/>
        <!--                    <sphere radius="${toeRadius}"/>-->
      </geometry>
      <material name="darkgray"/>
    </visual>
    <collision>
      <origin rpy="0 0 0" xyz="0 0 0"/>
      <geometry>
        <!--                    <box size="${toeRadius}*2 ${toeRadius}*2 ${toeRadius}*2"/>-->
        <sphere radius="0.0325"/>
      </geometry>
      <surface>
        <friction>
          <torsional>
            <coefficient>100000.0</coefficient>
            <surface_radius>100000</surface_radius>
            <use_patch_radius>false</use_patch_radius>
          </torsional>
          <ode>
            <mu>10000</mu>
            <mu2>10000</mu2>
          </ode>
        </friction>
        <contact>
          <ode>
            <kp>300000.0</kp>
            <kd>10000.0</kd>
          </ode>
        </contact>
      </surface>
    </collision>
    <inertial>
      <mass value="0.05"/>
      <inertia ixx="0.000025" ixy="0" ixz="0" iyy="0.000025" iyz="0" izz="0.000025"/>
      <!--		<inertia ixx="0.000025"  ixy="0"  ixz="0" iyy="0.000025" iyz="0" izz="0.000025" />-->
    </inertial>
  </link>
  <gazebo reference="toe1">
    <material>Gazebo/DarkGray</material>
    <collision>
      <surface>
        <bounce>
          <restitution_coefficient>0</restitution_coefficient>
          <threshold>1e+06</threshold>
        </bounce>
        <friction>
          <torsional>
            <coefficient>1.0</coefficient>
          </torsional>
          <ode>
            <mu>500.0</mu>
            <mu2>50000.0</mu2>
          </ode>
          <bullet>
            <rolling_friction>1.0</rolling_friction>
            <friction2>50000.0</friction2>
          </bullet>
        </friction>
        <contact>
          <bullet>
            <kp>300000.0</kp>
            <kd>10000.0</kd>
          </bullet>
          <ode>
            <kp>300000.0</kp>
            <kd>10000.0</kd>
          </ode>
        </contact>
      </surface>
    </collision>
  </gazebo>
  <joint name="jtoe1" type="fixed">
    <parent link="lower1"/>
    <child link="toe1"/>
    <origin xyz="0.3176 0 -0.0"/>
    <dynamics damping="0.0" friction="0.0"/>
  </joint>
  <!-- Hip motor -->
  <link name="hip2">
    <visual>
      <origin rpy="3.14159265359 0 0" xyz="0.0 0 0.0"/>
      <geometry>
        <mesh filename="package://ghost_description/meshes/Vision60_V4/V4_hip_transformed.stl" scale="1 1 1"/>
      </geometry>
      <material name="gray"/>
    </visual>
    <collision>
      <origin rpy="1.5707963268 0 0" xyz="-0.015 0.01 0"/>
      <geometry>
        <box size="0.19 0.09 0.14"/>
      </geometry>
    </collision>
    <inertial>
      <mass value="3.1"/>
      <!--		<mass value="1.975"/>-->
      <inertia ixx="0.01" ixy="0" ixz="0" iyy="0.01" iyz="0" izz="0.015"/>
      <!--		<inertia ixx="0.00891458"  ixy="0"  ixz="0" iyy="0.0100573" iyz="0" izz="0.01533698" />-->
    </inertial>
  </link>
  <gazebo reference="hip2">
    <material>Gazebo/DarkGray</material>
  </gazebo>
  <!-- Abduction joint. Joint names are: 8 9 10 11 -->
  <joint name="10" type="revolute">
    <parent link="body"/>
    <child link="hip2"/>
    <axis xyz="1 0 0"/>
    <origin xyz="0.308 -0.0955 0"/>
    <limit effort="375" lower="-0.53" upper="0.53" velocity="8.6"/>
    <dynamics damping="0.0" friction="0.0"/>
  </joint>
  <!-- Transmission elements required for Gazebo -->
  <transmission name="transmission_10">
    <type>transmission_interface/SimpleTransmission</type>
    <joint name="10">
      <hardwareInterface>hardware_interface/EffortJointInterface</hardwareInterface>
    </joint>
    <actuator name="motor_10">
      <hardwareInterface>EffortJointInterface</hardwareInterface>
      <mechanicalReduction>1</mechanicalReduction>
    </actuator>
  </transmission>
  <!-- Upper leg -->
  <link name="upper2">
    <visual>
      <!-- Right-->
      <origin rpy="0 0 0" xyz="0 0 0"/>
      <geometry>
        <mesh filename="package://ghost_description/meshes/Vision60_V4/V4_Upper_leg_mirrored_transformed.stl" scale="1 1 1"/>
      </geometry>
      <material name="gray"/>
    </visual>
    <collision>
      <origin rpy="0 0 0" xyz="-0.16 -0.0 0"/>
      <geometry>
        <box size="0.32 0.055 0.08"/>
      </geometry>
    </collision>
    <inertial>
      <mass value="2.7"/>
      <!--		<mass value="2.525"/>-->
      <inertia ixx="0.0003" ixy="0" ixz="0" iyy="0.004" iyz="0" izz="0.004"/>
      <!--		<inertia ixx="0.0003125"  ixy="0" ixz="0" iyy="0.0040625" iyz="0" izz="0.0040625" />-->
    </inertial>
  </link>
  <gazebo reference="upper2">
    <material>Gazebo/DarkGray</material>
  </gazebo>
  <!-- Hip joint. (Motor to upper leg). Joint names are: 0 2 4 6 -->
  <joint name="4" type="revolute">
    <parent link="hip2"/>
    <child link="upper2"/>
    <axis xyz="0 -1 0"/>
    <origin xyz="0 -0.0875 0"/>
    <!--  rpy="0 -0.3 0" -->
    <limit effort="87.5" lower="-6.28318530718" upper="6.28318530718" velocity="30"/>
    <dynamics damping="0.0" friction="0.0"/>
  </joint>
  <!-- Transmission elements required for Gazebo -->
  <transmission name="transmission_4">
    <type>transmission_interface/SimpleTransmission</type>
    <joint name="4">
      <hardwareInterface>hardware_interface/EffortJointInterface</hardwareInterface>
    </joint>
    <actuator name="motor_4">
      <hardwareInterface>EffortJointInterface</hardwareInterface>
      <mechanicalReduction>1</mechanicalReduction>
    </actuator>
  </transmission>
  <!-- Lower leg -->
  <link name="lower2">
    <visual>
      <!-- Right-->
      <origin rpy="0 0 0" xyz="0 -0.02 0"/>
      <geometry>
        <mesh filename="package://ghost_description/meshes/Vision60_V4/V4_Lower_leg_transformed.stl" scale="1 1 1"/>
      </geometry>
      <material name="gray"/>
    </visual>
    <collision>
      <origin rpy="0 1.5707963268 0" xyz="0.1588 0 0"/>
      <geometry>
        <cylinder length="0.3176" radius="0.02"/>
      </geometry>
    </collision>
    <inertial>
      <mass value="0.65"/>
      <!--		<mass value="0.375"/>-->
      <inertia ixx="0.001" ixy="0" ixz="0" iyy="0.001" iyz="0" izz="0.0001"/>
      <!--		<inertia ixx="0.00131075"  ixy="0"  ixz="0" iyy="0.00131075" iyz="0" izz="0.0001" />-->
    </inertial>
  </link>
  <gazebo reference="lower2">
    <material>Gazebo/DarkGray</material>
  </gazebo>
  <!-- Knee joint. Joint names are: 1 3 5 7 -->
  <joint name="5" type="revolute">
    <parent link="upper2"/>
    <child link="lower2"/>
    <axis xyz="0 1 0"/>
    <origin xyz="-0.32 0 0"/>
    <!--rpy="0 0.5 0"-->
    <limit effort="87.5" lower="0" upper="3.14159265359" velocity="30"/>
    <dynamics damping="0.0" friction="0.0"/>
  </joint>
  <!-- Transmission elements required for Gazebo -->
  <transmission name="transmission_5">
    <type>transmission_interface/SimpleTransmission</type>
    <joint name="5">
      <hardwareInterface>hardware_interface/EffortJointInterface</hardwareInterface>
    </joint>
    <actuator name="motor_5">
      <hardwareInterface>EffortJointInterface</hardwareInterface>
      <mechanicalReduction>1</mechanicalReduction>
    </actuator>
  </transmission>
  <!-- Toe -->
  <link name="toe2">
    <!--            <contact>-->
    <!--                <friction_anchor/>-->
    <!--                <stiffness value="${toeStiffness}"/>-->
    <!--                <damping value="${toeDamping}"/>-->
    <!--                <spinning_friction value="${toeSpinningFriction}"/>-->
    <!--                <lateral_friction value="${toeLateralFriction}"/>-->
    <!--            </contact>-->
    <visual>
      <origin rpy="0 0 0" xyz="0 0 0"/>
      <geometry>
        <!--                     <box size="${toeRadius}*2 ${toeRadius}*2 ${toeRadius}*2"/>-->
        <sphere radius="0.001"/>
        <!--                    <sphere radius="${toeRadius}"/>-->
      </geometry>
      <material name="darkgray"/>
    </visual>
    <collision>
      <origin rpy="0 0 0" xyz="0 0 0"/>
      <geometry>
        <!--                    <box size="${toeRadius}*2 ${toeRadius}*2 ${toeRadius}*2"/>-->
        <sphere radius="0.0325"/>
      </geometry>
      <surface>
        <friction>
          <torsional>
            <coefficient>100000.0</coefficient>
            <surface_radius>100000</surface_radius>
            <use_patch_radius>false</use_patch_radius>
          </torsional>
          <ode>
            <mu>10000</mu>
            <mu2>10000</mu2>
          </ode>
        </friction>
        <contact>
          <ode>
            <kp>300000.0</kp>
            <kd>10000.0</kd>
          </ode>
        </contact>
      </surface>
    </collision>
    <inertial>
      <mass value="0.05"/>
      <inertia ixx="0.000025" ixy="0" ixz="0" iyy="0.000025" iyz="0" izz="0.000025"/>
      <!--		<inertia ixx="0.000025"  ixy="0"  ixz="0" iyy="0.000025" iyz="0" izz="0.000025" />-->
    </inertial>
  </link>
  <gazebo reference="toe2">
    <material>Gazebo/DarkGray</material>
    <collision>
      <surface>
        <bounce>
          <restitution_coefficient>0</restitution_coefficient>
          <threshold>1e+06</threshold>
        </bounce>
        <friction>
          <torsional>
            <coefficient>1.0</coefficient>
          </torsional>
          <ode>
            <mu>500.0</mu>
            <mu2>50000.0</mu2>
          </ode>
          <bullet>
            <rolling_friction>1.0</rolling_friction>
            <friction2>50000.0</friction2>
          </bullet>
        </friction>
        <contact>
          <bullet>
            <kp>300000.0</kp>
            <kd>10000.0</kd>
          </bullet>
          <ode>
            <kp>300000.0</kp>
            <kd>10000.0</kd>
          </ode>
        </contact>
      </surface>
    </collision>
  </gazebo>
  <joint name="jtoe2" type="fixed">
    <parent link="lower2"/>
    <child link="toe2"/>
    <origin xyz="0.3176 0 -0.0"/>
    <dynamics damping="0.0" friction="0.0"/>
  </joint>
  <!-- Hip motor -->
  <link name="hip3">
    <visual>
      <origin rpy="3.14159265359 3.14159265359 0" xyz="0.0 0.0 0.0"/>
      <geometry>
        <mesh filename="package://ghost_description/meshes/Vision60_V4/V4_hip_transformed.stl" scale="1 1 1"/>
      </geometry>
      <material name="gray"/>
    </visual>
    <collision>
      <origin rpy="1.5707963268 0 0" xyz="0.015 0.01 0"/>
      <geometry>
        <box size="0.19 0.09 0.14"/>
      </geometry>
    </collision>
    <inertial>
      <mass value="3.1"/>
      <!--		<mass value="1.975"/>-->
      <inertia ixx="0.01" ixy="0" ixz="0" iyy="0.01" iyz="0" izz="0.015"/>
      <!--		<inertia ixx="0.00891458"  ixy="0"  ixz="0" iyy="0.0100573" iyz="0" izz="0.01533698" />-->
    </inertial>
  </link>
  <gazebo reference="hip3">
    <material>Gazebo/DarkGray</material>
  </gazebo>
  <!-- Abduction joint. Joint names are: 8 9 10 11 -->
  <joint name="11" type="revolute">
    <parent link="body"/>
    <child link="hip3"/>
    <axis xyz="1 0 0"/>
    <origin xyz="-0.308 -0.0955 0"/>
    <limit effort="375" lower="-0.53" upper="0.53" velocity="8.6"/>
    <dynamics damping="0.0" friction="0.0"/>
  </joint>
  <!-- Transmission elements required for Gazebo -->
  <transmission name="transmission_11">
    <type>transmission_interface/SimpleTransmission</type>
    <joint name="11">
      <hardwareInterface>hardware_interface/EffortJointInterface</hardwareInterface>
    </joint>
    <actuator name="motor_11">
      <hardwareInterface>EffortJointInterface</hardwareInterface>
      <mechanicalReduction>1</mechanicalReduction>
    </actuator>
  </transmission>
  <!-- Upper leg -->
  <link name="upper3">
    <visual>
      <!-- Right-->
      <origin rpy="0 0 0" xyz="0 0 0"/>
      <geometry>
        <mesh filename="package://ghost_description/meshes/Vision60_V4/V4_Upper_leg_mirrored_transformed.stl" scale="1 1 1"/>
      </geometry>
      <material name="gray"/>
    </visual>
    <collision>
      <origin rpy="0 0 0" xyz="-0.16 -0.0 0"/>
      <geometry>
        <box size="0.32 0.055 0.08"/>
      </geometry>
    </collision>
    <inertial>
      <mass value="2.7"/>
      <!--		<mass value="2.525"/>-->
      <inertia ixx="0.0003" ixy="0" ixz="0" iyy="0.004" iyz="0" izz="0.004"/>
      <!--		<inertia ixx="0.0003125"  ixy="0" ixz="0" iyy="0.0040625" iyz="0" izz="0.0040625" />-->
    </inertial>
  </link>
  <gazebo reference="upper3">
    <material>Gazebo/DarkGray</material>
  </gazebo>
  <!-- Hip joint. (Motor to upper leg). Joint names are: 0 2 4 6 -->
  <joint name="6" type="revolute">
    <parent link="hip3"/>
    <child link="upper3"/>
    <axis xyz="0 -1 0"/>
    <origin xyz="0 -0.0875 0"/>
    <!--  rpy="0 -0.3 0" -->
    <limit effort="87.5" lower="-6.28318530718" upper="6.28318530718" velocity="30"/>
    <dynamics damping="0.0" friction="0.0"/>
  </joint>
  <!-- Transmission elements required for Gazebo -->
  <transmission name="transmission_6">
    <type>transmission_interface/SimpleTransmission</type>
    <joint name="6">
      <hardwareInterface>hardware_interface/EffortJointInterface</hardwareInterface>
    </joint>
    <actuator name="motor_6">
      <hardwareInterface>EffortJointInterface</hardwareInterface>
      <mechanicalReduction>1</mechanicalReduction>
    </actuator>
  </transmission>
  <!-- Lower leg -->
  <link name="lower3">
    <visual>
      <!-- Right-->
      <origin rpy="0 0 0" xyz="0 -0.02 0"/>
      <geometry>
        <mesh filename="package://ghost_description/meshes/Vision60_V4/V4_Lower_leg_transformed.stl" scale="1 1 1"/>
      </geometry>
      <material name="gray"/>
    </visual>
    <collision>
      <origin rpy="0 1.5707963268 0" xyz="0.1588 0 0"/>
      <geometry>
        <cylinder length="0.3176" radius="0.02"/>
      </geometry>
    </collision>
    <inertial>
      <mass value="0.65"/>
      <!--		<mass value="0.375"/>-->
      <inertia ixx="0.001" ixy="0" ixz="0" iyy="0.001" iyz="0" izz="0.0001"/>
      <!--		<inertia ixx="0.00131075"  ixy="0"  ixz="0" iyy="0.00131075" iyz="0" izz="0.0001" />-->
    </inertial>
  </link>
  <gazebo reference="lower3">
    <material>Gazebo/DarkGray</material>
  </gazebo>
  <!-- Knee joint. Joint names are: 1 3 5 7 -->
  <joint name="7" type="revolute">
    <parent link="upper3"/>
    <child link="lower3"/>
    <axis xyz="0 1 0"/>
    <origin xyz="-0.32 0 0"/>
    <!--rpy="0 0.5 0"-->
    <limit effort="87.5" lower="0" upper="3.14159265359" velocity="30"/>
    <dynamics damping="0.0" friction="0.0"/>
  </joint>
  <!-- Transmission elements required for Gazebo -->
  <transmission name="transmission_7">
    <type>transmission_interface/SimpleTransmission</type>
    <joint name="7">
      <hardwareInterface>hardware_interface/EffortJointInterface</hardwareInterface>
    </joint>
    <actuator name="motor_7">
      <hardwareInterface>EffortJointInterface</hardwareInterface>
      <mechanicalReduction>1</mechanicalReduction>
    </actuator>
  </transmission>
  <!-- Toe -->
  <link name="toe3">
    <!--            <contact>-->
    <!--                <friction_anchor/>-->
    <!--                <stiffness value="${toeStiffness}"/>-->
    <!--                <damping value="${toeDamping}"/>-->
    <!--                <spinning_friction value="${toeSpinningFriction}"/>-->
    <!--                <lateral_friction value="${toeLateralFriction}"/>-->
    <!--            </contact>-->
    <visual>
      <origin rpy="0 0 0" xyz="0 0 0"/>
      <geometry>
        <!--                     <box size="${toeRadius}*2 ${toeRadius}*2 ${toeRadius}*2"/>-->
        <sphere radius="0.001"/>
        <!--                    <sphere radius="${toeRadius}"/>-->
      </geometry>
      <material name="darkgray"/>
    </visual>
    <collision>
      <origin rpy="0 0 0" xyz="0 0 0"/>
      <geometry>
        <!--                    <box size="${toeRadius}*2 ${toeRadius}*2 ${toeRadius}*2"/>-->
        <sphere radius="0.0325"/>
      </geometry>
      <surface>
        <friction>
          <torsional>
            <coefficient>100000.0</coefficient>
            <surface_radius>100000</surface_radius>
            <use_patch_radius>false</use_patch_radius>
          </torsional>
          <ode>
            <mu>10000</mu>
            <mu2>10000</mu2>
          </ode>
        </friction>
        <contact>
          <ode>
            <kp>300000.0</kp>
            <kd>10000.0</kd>
          </ode>
        </contact>
      </surface>
    </collision>
    <inertial>
      <mass value="0.05"/>
      <inertia ixx="0.000025" ixy="0" ixz="0" iyy="0.000025" iyz="0" izz="0.000025"/>
      <!--		<inertia ixx="0.000025"  ixy="0"  ixz="0" iyy="0.000025" iyz="0" izz="0.000025" />-->
    </inertial>
  </link>
  <gazebo reference="toe3">
    <material>Gazebo/DarkGray</material>
    <collision>
      <surface>
        <bounce>
          <restitution_coefficient>0</restitution_coefficient>
          <threshold>1e+06</threshold>
        </bounce>
        <friction>
          <torsional>
            <coefficient>1.0</coefficient>
          </torsional>
          <ode>
            <mu>500.0</mu>
            <mu2>50000.0</mu2>
          </ode>
          <bullet>
            <rolling_friction>1.0</rolling_friction>
            <friction2>50000.0</friction2>
          </bullet>
        </friction>
        <contact>
          <bullet>
            <kp>300000.0</kp>
            <kd>10000.0</kd>
          </bullet>
          <ode>
            <kp>300000.0</kp>
            <kd>10000.0</kd>
          </ode>
        </contact>
      </surface>
    </collision>
  </gazebo>
  <joint name="jtoe3" type="fixed">
    <parent link="lower3"/>
    <child link="toe3"/>
    <origin xyz="0.3176 0 -0.0"/>
    <dynamics damping="0.0" friction="0.0"/>
  </joint>
  <!-- Add ros_control plugin -->
  <gazebo>
    <plugin filename="libgazebo_ros_control.so" name="gazebo_ros_control">
      <robotNamespace>//vision60</robotNamespace>
    </plugin>
  </gazebo>
</robot>

