<?xml version="1.0" ?>
<!-- =================================================================================== -->
<!-- |    This document was autogenerated by xacro from vision60_v5_composite.urdf.xacro | -->
<!-- |    EDITING THIS FILE BY HAND IS NOT RECOMMENDED                                 | -->
<!-- =================================================================================== -->
<!--
 * Copyright (C) 2020 Ghost Robotics - All Rights Reserved
 * Unauthorized copying of this file, via any medium is strictly prohibited
 * Proprietary and confidential
-->
<robot name="vision60_composite">
  <!-- Define materials -->
  <material name="gray">
    <color rgba="0.5 0.5 0.5 1.0"/>
  </material>
  <material name="darkgray">
    <color rgba="0.3 0.3 0.3 1.0"/>
  </material>
  <material name="blue">
    <color rgba="0 0 0.8 1"/>
  </material>
  <material name="black">
    <color rgba="0 0 0 1"/>
  </material>
  <material name="purple">
    <color rgba="0.5 0.0 0.5 1.0"/>
  </material>
  <material name="red">
    <color rgba="0.8 0.0 0.2 1.0"/>
  </material>
  <!-- 1=stylish boxes, 0=appropriate meshes -->
  <!-- Body -->
  <link name="body">
    <visual>
      <origin rpy="0 0 0" xyz="0 0 0"/>
      <geometry>
        <mesh filename="package://ghost_description/meshes/Vision60_V4/decimated/V4_frame_transformed_decimated.stl" scale="1 1 1"/>
      </geometry>
      <material name="gray"/>
    </visual>
    <inertial>
      <origin rpy="0 0 0" xyz="-0.00068 -4e-05 -0.01148"/>
      <!--			<mass value="14.49326" />-->
      <mass value="13.600000000000001"/>
      <inertia ixx="0.13966910635" ixy="0.00216000038" ixz="-0.00087481805" iyy="0.60012721094" iyz="-9.986679e-05" izz="0.61763591657"/>
    </inertial>
    <collision>
      <origin rpy="0 0 0" xyz="0 0 0"/>
      <geometry>
        <box size="0.83 0.245 0.16"/>
      </geometry>
    </collision>
  </link>
  <!-- Hip motor -->
  <link name="hip0">
    <visual>
      <origin rpy="0 0 0" xyz="0 0.0 0"/>
      <geometry>
        <mesh filename="package://ghost_description/meshes/Vision60_V4/decimated/V4_hip_transformed_decimated.stl" scale="1 1 1"/>
      </geometry>
      <material name="gray"/>
    </visual>
    <inertial>
      <origin rpy="0 0 0" xyz="-0.0215 0.00241 0.0007"/>
      <!--			<mass value="2.16596" />-->
      <mass value="3.1"/>
      <inertia ixx="0.0038547528" ixy="3.461207e-05" ixz="-9.7936e-06" iyy="0.00851695491" iyz="-2.432235e-05" izz="0.0095299342"/>
    </inertial>
    <collision>
      <origin rpy="1.570796326795 0 0" xyz="-0.0271 -0.0050000000000000044 0"/>
      <geometry>
        <box size="0.19 0.09 0.14"/>
      </geometry>
    </collision>
  </link>
  <!-- Abduction joint. Joint names are: 8 9 10 11 -->
  <joint name="8" type="revolute">
    <parent link="body"/>
    <child link="hip0"/>
    <axis xyz="1 0 0"/>
    <origin xyz="0.308 0.0955 0"/>
    <limit effort="375" lower="-0.53" upper="0.53" velocity="8.6"/>
    <dynamics damping="0.0" friction="0.0"/>
  </joint>
  <!-- Upper leg -->
  <link name="upper0">
    <visual>
      <origin rpy="3.14159265359 0 0" xyz="0 0 0"/>
      <geometry>
        <mesh filename="package://ghost_description/meshes/Vision60_V4/decimated/V4_Upper_leg_transformed_decimated.stl" scale="1 1 1"/>
      </geometry>
      <material name="gray"/>
    </visual>
    <inertial>
      <origin rpy="0 0 0" xyz="0.14434 0.0 0.00186"/>
      <!--			<mass value="0.56268" />-->
      <mass value="0.65"/>
      <inertia ixx="0.00016212522" ixy="1.5074e-07" ixz="0.00041126588" iyy="0.01114596692" iyz="2.2276e-07" izz="0.01110311429"/>
    </inertial>
    <collision>
      <origin rpy="0 0 0" xyz="-0.17005 0.0 0"/>
      <geometry>
        <box size="0.3401 0.114 0.08"/>
      </geometry>
    </collision>
  </link>
  <!-- Hip joint. (Motor to upper leg). Joint names are: 0 2 4 6 -->
  <joint name="0" type="revolute">
    <parent link="hip0"/>
    <child link="upper0"/>
    <axis xyz="0 -1 0"/>
    <origin xyz="0 0.122 0"/>
    <!--  rpy="0 -0.3 0" -->
    <limit effort="87.5" lower="-6.28318530718" upper="6.28318530718" velocity="30"/>
    <dynamics damping="0.0" friction="0.0"/>
  </joint>
  <!-- Lower leg -->
  <link name="lower0">
    <visual>
      <origin rpy="0 0 0" xyz="0 0.0 0"/>
      <geometry>
        <mesh filename="package://ghost_description/meshes/Vision60_V4/decimated/V4_Lower_leg_transformed_decimated.stl" scale="1 1 1"/>
      </geometry>
      <material name="gray"/>
    </visual>
    <inertial>
      <origin rpy="0 0 0" xyz="-0.08855 0.00019 -0.00132"/>
      <!--			<mass value="2.82064" />-->
      <mass value="2.7"/>
      <inertia ixx="0.0026343095" ixy="2.111775e-05" ixz="0.00085593451" iyy="0.03517854533" iyz="1.97622e-06" izz="0.03531304953"/>
    </inertial>
    <collision>
      <origin rpy="0 1.570796326795 0" xyz="0.168215 0 0"/>
      <geometry>
        <cylinder length="0.33643" radius="0.02"/>
      </geometry>
    </collision>
  </link>
  <!-- Knee joint. Joint names are: 1 3 5 7 -->
  <joint name="1" type="revolute">
    <parent link="upper0"/>
    <child link="lower0"/>
    <axis xyz="0 1 0"/>
    <origin xyz="-0.3401 0 -0.0325"/>
    <!--rpy="0 0.5 0"-->
    <limit effort="87.5" lower="0" upper="3.14159265359" velocity="30"/>
    <dynamics damping="0.0" friction="0.0"/>
  </joint>
  <!-- Toe -->
  <link name="toe0">
    <visual>
      <origin rpy="0 0 0" xyz="0 0 0"/>
      <geometry>
        <sphere radius="0.001"/>
      </geometry>
      <material name="darkgray"/>
    </visual>
    <collision name="toe0_collision">
      <origin rpy="0 0 0" xyz="0 0 0"/>
      <geometry>
        <sphere radius="0.0325"/>
      </geometry>
      <surface>
        <friction>
          <torsional>
            <coefficient>100000.0</coefficient>
            <surface_radius>100000</surface_radius>
            <use_patch_radius>false</use_patch_radius>
          </torsional>
          <ode>
            <mu>10000</mu>
            <mu2>10000</mu2>
          </ode>
        </friction>
        <contact>
          <ode>
            <kp>300000.0</kp>
            <kd>10000.0</kd>
          </ode>
        </contact>
      </surface>
    </collision>
    <inertial>
      <mass value="0.05"/>
      <inertia ixx="0.000025" ixy="0" ixz="0" iyy="0.000025" iyz="0" izz="0.000025"/>
    </inertial>
  </link>
  <joint name="jtoe0" type="fixed">
    <parent link="lower0"/>
    <child link="toe0"/>
    <origin xyz="0.33643 0 -0.00628"/>
    <dynamics damping="0.0" friction="0.0"/>
  </joint>
  <!-- Hip motor -->
  <link name="hip1">
    <visual>
      <origin rpy="0 3.14159265359 0" xyz="0.0 0.0 0"/>
      <geometry>
        <mesh filename="package://ghost_description/meshes/Vision60_V4/decimated/V4_hip_transformed_decimated.stl" scale="1 1 1"/>
      </geometry>
      <material name="gray"/>
    </visual>
    <inertial>
      <origin rpy="0 0 0" xyz="-0.0215 0.00241 0.0007"/>
      <!--			<mass value="2.16596" />-->
      <mass value="3.1"/>
      <inertia ixx="0.0038547528" ixy="3.461207e-05" ixz="-9.7936e-06" iyy="0.00851695491" iyz="-2.432235e-05" izz="0.0095299342"/>
    </inertial>
    <collision>
      <origin rpy="1.570796326795 0 0" xyz="0.0271 -0.0050000000000000044 0"/>
      <geometry>
        <box size="0.19 0.09 0.14"/>
      </geometry>
    </collision>
  </link>
  <!-- Abduction joint. Joint names are: 8 9 10 11 -->
  <joint name="9" type="revolute">
    <parent link="body"/>
    <child link="hip1"/>
    <axis xyz="1 0 0"/>
    <origin xyz="-0.308 0.0955 0"/>
    <limit effort="375" lower="-0.53" upper="0.53" velocity="8.6"/>
    <dynamics damping="0.0" friction="0.0"/>
  </joint>
  <!-- Upper leg -->
  <link name="upper1">
    <visual>
      <origin rpy="3.14159265359 0 0" xyz="0 0 0"/>
      <geometry>
        <mesh filename="package://ghost_description/meshes/Vision60_V4/decimated/V4_Upper_leg_transformed_decimated.stl" scale="1 1 1"/>
      </geometry>
      <material name="gray"/>
    </visual>
    <inertial>
      <origin rpy="0 0 0" xyz="0.14434 0.0 0.00186"/>
      <!--			<mass value="0.56268" />-->
      <mass value="0.65"/>
      <inertia ixx="0.00016212522" ixy="1.5074e-07" ixz="0.00041126588" iyy="0.01114596692" iyz="2.2276e-07" izz="0.01110311429"/>
    </inertial>
    <collision>
      <origin rpy="0 0 0" xyz="-0.17005 0.0 0"/>
      <geometry>
        <box size="0.3401 0.114 0.08"/>
      </geometry>
    </collision>
  </link>
  <!-- Hip joint. (Motor to upper leg). Joint names are: 0 2 4 6 -->
  <joint name="2" type="revolute">
    <parent link="hip1"/>
    <child link="upper1"/>
    <axis xyz="0 -1 0"/>
    <origin xyz="0 0.122 0"/>
    <!--  rpy="0 -0.3 0" -->
    <limit effort="87.5" lower="-6.28318530718" upper="6.28318530718" velocity="30"/>
    <dynamics damping="0.0" friction="0.0"/>
  </joint>
  <!-- Lower leg -->
  <link name="lower1">
    <visual>
      <origin rpy="0 0 0" xyz="0 0.0 0"/>
      <geometry>
        <mesh filename="package://ghost_description/meshes/Vision60_V4/decimated/V4_Lower_leg_transformed_decimated.stl" scale="1 1 1"/>
      </geometry>
      <material name="gray"/>
    </visual>
    <inertial>
      <origin rpy="0 0 0" xyz="-0.08855 0.00019 -0.00132"/>
      <!--			<mass value="2.82064" />-->
      <mass value="2.7"/>
      <inertia ixx="0.0026343095" ixy="2.111775e-05" ixz="0.00085593451" iyy="0.03517854533" iyz="1.97622e-06" izz="0.03531304953"/>
    </inertial>
    <collision>
      <origin rpy="0 1.570796326795 0" xyz="0.168215 0 0"/>
      <geometry>
        <cylinder length="0.33643" radius="0.02"/>
      </geometry>
    </collision>
  </link>
  <!-- Knee joint. Joint names are: 1 3 5 7 -->
  <joint name="3" type="revolute">
    <parent link="upper1"/>
    <child link="lower1"/>
    <axis xyz="0 1 0"/>
    <origin xyz="-0.3401 0 -0.0325"/>
    <!--rpy="0 0.5 0"-->
    <limit effort="87.5" lower="0" upper="3.14159265359" velocity="30"/>
    <dynamics damping="0.0" friction="0.0"/>
  </joint>
  <!-- Toe -->
  <link name="toe1">
    <visual>
      <origin rpy="0 0 0" xyz="0 0 0"/>
      <geometry>
        <sphere radius="0.001"/>
      </geometry>
      <material name="darkgray"/>
    </visual>
    <collision name="toe1_collision">
      <origin rpy="0 0 0" xyz="0 0 0"/>
      <geometry>
        <sphere radius="0.0325"/>
      </geometry>
      <surface>
        <friction>
          <torsional>
            <coefficient>100000.0</coefficient>
            <surface_radius>100000</surface_radius>
            <use_patch_radius>false</use_patch_radius>
          </torsional>
          <ode>
            <mu>10000</mu>
            <mu2>10000</mu2>
          </ode>
        </friction>
        <contact>
          <ode>
            <kp>300000.0</kp>
            <kd>10000.0</kd>
          </ode>
        </contact>
      </surface>
    </collision>
    <inertial>
      <mass value="0.05"/>
      <inertia ixx="0.000025" ixy="0" ixz="0" iyy="0.000025" iyz="0" izz="0.000025"/>
    </inertial>
  </link>
  <joint name="jtoe1" type="fixed">
    <parent link="lower1"/>
    <child link="toe1"/>
    <origin xyz="0.33643 0 -0.00628"/>
    <dynamics damping="0.0" friction="0.0"/>
  </joint>
  <!-- Hip motor -->
  <link name="hip2">
    <visual>
      <origin rpy="3.14159265359 0 0" xyz="0.0 0 0.0"/>
      <geometry>
        <mesh filename="package://ghost_description/meshes/Vision60_V4/decimated/V4_hip_transformed_decimated.stl" scale="1 1 1"/>
      </geometry>
      <material name="gray"/>
    </visual>
    <inertial>
      <origin rpy="0 0 0" xyz="-0.0215 0.00241 0.0007"/>
      <!--			<mass value="2.16596" />-->
      <mass value="3.1"/>
      <inertia ixx="0.0038547528" ixy="3.461207e-05" ixz="-9.7936e-06" iyy="0.00851695491" iyz="-2.432235e-05" izz="0.0095299342"/>
    </inertial>
    <collision>
      <origin rpy="1.570796326795 0 0" xyz="-0.0271 0.0050000000000000044 0"/>
      <geometry>
        <box size="0.19 0.09 0.14"/>
      </geometry>
    </collision>
  </link>
  <!-- Abduction joint. Joint names are: 8 9 10 11 -->
  <joint name="10" type="revolute">
    <parent link="body"/>
    <child link="hip2"/>
    <axis xyz="1 0 0"/>
    <origin xyz="0.308 -0.0955 0"/>
    <limit effort="375" lower="-0.53" upper="0.53" velocity="8.6"/>
    <dynamics damping="0.0" friction="0.0"/>
  </joint>
  <!-- Upper leg -->
  <link name="upper2">
    <visual>
      <!-- Right-->
      <origin rpy="0 0 0" xyz="0 0 0"/>
      <geometry>
        <mesh filename="package://ghost_description/meshes/Vision60_V4/decimated/V4_Upper_leg_mirrored_transformed_decimated.stl" scale="1 1 1"/>
      </geometry>
      <material name="gray"/>
    </visual>
    <inertial>
      <origin rpy="0 0 0" xyz="0.14434 0.0 0.00186"/>
      <!--			<mass value="0.56268" />-->
      <mass value="0.65"/>
      <inertia ixx="0.00016212522" ixy="1.5074e-07" ixz="0.00041126588" iyy="0.01114596692" iyz="2.2276e-07" izz="0.01110311429"/>
    </inertial>
    <collision>
      <origin rpy="0 0 0" xyz="-0.17005 -0.0 0"/>
      <geometry>
        <box size="0.3401 0.114 0.08"/>
      </geometry>
    </collision>
  </link>
  <!-- Hip joint. (Motor to upper leg). Joint names are: 0 2 4 6 -->
  <joint name="4" type="revolute">
    <parent link="hip2"/>
    <child link="upper2"/>
    <axis xyz="0 -1 0"/>
    <origin xyz="0 -0.122 0"/>
    <!--  rpy="0 -0.3 0" -->
    <limit effort="87.5" lower="-6.28318530718" upper="6.28318530718" velocity="30"/>
    <dynamics damping="0.0" friction="0.0"/>
  </joint>
  <!-- Lower leg -->
  <link name="lower2">
    <visual>
      <origin rpy="0 0 0" xyz="0 0.0 0"/>
      <geometry>
        <mesh filename="package://ghost_description/meshes/Vision60_V4/decimated/V4_Lower_leg_transformed_decimated.stl" scale="1 1 1"/>
      </geometry>
      <material name="gray"/>
    </visual>
    <inertial>
      <origin rpy="0 0 0" xyz="-0.08855 0.00019 -0.00132"/>
      <!--			<mass value="2.82064" />-->
      <mass value="2.7"/>
      <inertia ixx="0.0026343095" ixy="2.111775e-05" ixz="0.00085593451" iyy="0.03517854533" iyz="1.97622e-06" izz="0.03531304953"/>
    </inertial>
    <collision>
      <origin rpy="0 1.570796326795 0" xyz="0.168215 0 0"/>
      <geometry>
        <cylinder length="0.33643" radius="0.02"/>
      </geometry>
    </collision>
  </link>
  <!-- Knee joint. Joint names are: 1 3 5 7 -->
  <joint name="5" type="revolute">
    <parent link="upper2"/>
    <child link="lower2"/>
    <axis xyz="0 1 0"/>
    <origin xyz="-0.3401 0 -0.0325"/>
    <!--rpy="0 0.5 0"-->
    <limit effort="87.5" lower="0" upper="3.14159265359" velocity="30"/>
    <dynamics damping="0.0" friction="0.0"/>
  </joint>
  <!-- Toe -->
  <link name="toe2">
    <visual>
      <origin rpy="0 0 0" xyz="0 0 0"/>
      <geometry>
        <sphere radius="0.001"/>
      </geometry>
      <material name="darkgray"/>
    </visual>
    <collision name="toe2_collision">
      <origin rpy="0 0 0" xyz="0 0 0"/>
      <geometry>
        <sphere radius="0.0325"/>
      </geometry>
      <surface>
        <friction>
          <torsional>
            <coefficient>100000.0</coefficient>
            <surface_radius>100000</surface_radius>
            <use_patch_radius>false</use_patch_radius>
          </torsional>
          <ode>
            <mu>10000</mu>
            <mu2>10000</mu2>
          </ode>
        </friction>
        <contact>
          <ode>
            <kp>300000.0</kp>
            <kd>10000.0</kd>
          </ode>
        </contact>
      </surface>
    </collision>
    <inertial>
      <mass value="0.05"/>
      <inertia ixx="0.000025" ixy="0" ixz="0" iyy="0.000025" iyz="0" izz="0.000025"/>
    </inertial>
  </link>
  <joint name="jtoe2" type="fixed">
    <parent link="lower2"/>
    <child link="toe2"/>
    <origin xyz="0.33643 0 -0.00628"/>
    <dynamics damping="0.0" friction="0.0"/>
  </joint>
  <!-- Hip motor -->
  <link name="hip3">
    <visual>
      <origin rpy="3.14159265359 3.14159265359 0" xyz="0.0 0.0 0.0"/>
      <geometry>
        <mesh filename="package://ghost_description/meshes/Vision60_V4/decimated/V4_hip_transformed_decimated.stl" scale="1 1 1"/>
      </geometry>
      <material name="gray"/>
    </visual>
    <inertial>
      <origin rpy="0 0 0" xyz="-0.0215 0.00241 0.0007"/>
      <!--			<mass value="2.16596" />-->
      <mass value="3.1"/>
      <inertia ixx="0.0038547528" ixy="3.461207e-05" ixz="-9.7936e-06" iyy="0.00851695491" iyz="-2.432235e-05" izz="0.0095299342"/>
    </inertial>
    <collision>
      <origin rpy="1.570796326795 0 0" xyz="0.0271 0.0050000000000000044 0"/>
      <geometry>
        <box size="0.19 0.09 0.14"/>
      </geometry>
    </collision>
  </link>
  <!-- Abduction joint. Joint names are: 8 9 10 11 -->
  <joint name="11" type="revolute">
    <parent link="body"/>
    <child link="hip3"/>
    <axis xyz="1 0 0"/>
    <origin xyz="-0.308 -0.0955 0"/>
    <limit effort="375" lower="-0.53" upper="0.53" velocity="8.6"/>
    <dynamics damping="0.0" friction="0.0"/>
  </joint>
  <!-- Upper leg -->
  <link name="upper3">
    <visual>
      <!-- Right-->
      <origin rpy="0 0 0" xyz="0 0 0"/>
      <geometry>
        <mesh filename="package://ghost_description/meshes/Vision60_V4/decimated/V4_Upper_leg_mirrored_transformed_decimated.stl" scale="1 1 1"/>
      </geometry>
      <material name="gray"/>
    </visual>
    <inertial>
      <origin rpy="0 0 0" xyz="0.14434 0.0 0.00186"/>
      <!--			<mass value="0.56268" />-->
      <mass value="0.65"/>
      <inertia ixx="0.00016212522" ixy="1.5074e-07" ixz="0.00041126588" iyy="0.01114596692" iyz="2.2276e-07" izz="0.01110311429"/>
    </inertial>
    <collision>
      <origin rpy="0 0 0" xyz="-0.17005 -0.0 0"/>
      <geometry>
        <box size="0.3401 0.114 0.08"/>
      </geometry>
    </collision>
  </link>
  <!-- Hip joint. (Motor to upper leg). Joint names are: 0 2 4 6 -->
  <joint name="6" type="revolute">
    <parent link="hip3"/>
    <child link="upper3"/>
    <axis xyz="0 -1 0"/>
    <origin xyz="0 -0.122 0"/>
    <!--  rpy="0 -0.3 0" -->
    <limit effort="87.5" lower="-6.28318530718" upper="6.28318530718" velocity="30"/>
    <dynamics damping="0.0" friction="0.0"/>
  </joint>
  <!-- Lower leg -->
  <link name="lower3">
    <visual>
      <origin rpy="0 0 0" xyz="0 0.0 0"/>
      <geometry>
        <mesh filename="package://ghost_description/meshes/Vision60_V4/decimated/V4_Lower_leg_transformed_decimated.stl" scale="1 1 1"/>
      </geometry>
      <material name="gray"/>
    </visual>
    <inertial>
      <origin rpy="0 0 0" xyz="-0.08855 0.00019 -0.00132"/>
      <!--			<mass value="2.82064" />-->
      <mass value="2.7"/>
      <inertia ixx="0.0026343095" ixy="2.111775e-05" ixz="0.00085593451" iyy="0.03517854533" iyz="1.97622e-06" izz="0.03531304953"/>
    </inertial>
    <collision>
      <origin rpy="0 1.570796326795 0" xyz="0.168215 0 0"/>
      <geometry>
        <cylinder length="0.33643" radius="0.02"/>
      </geometry>
    </collision>
  </link>
  <!-- Knee joint. Joint names are: 1 3 5 7 -->
  <joint name="7" type="revolute">
    <parent link="upper3"/>
    <child link="lower3"/>
    <axis xyz="0 1 0"/>
    <origin xyz="-0.3401 0 -0.0325"/>
    <!--rpy="0 0.5 0"-->
    <limit effort="87.5" lower="0" upper="3.14159265359" velocity="30"/>
    <dynamics damping="0.0" friction="0.0"/>
  </joint>
  <!-- Toe -->
  <link name="toe3">
    <visual>
      <origin rpy="0 0 0" xyz="0 0 0"/>
      <geometry>
        <sphere radius="0.001"/>
      </geometry>
      <material name="darkgray"/>
    </visual>
    <collision name="toe3_collision">
      <origin rpy="0 0 0" xyz="0 0 0"/>
      <geometry>
        <sphere radius="0.0325"/>
      </geometry>
      <surface>
        <friction>
          <torsional>
            <coefficient>100000.0</coefficient>
            <surface_radius>100000</surface_radius>
            <use_patch_radius>false</use_patch_radius>
          </torsional>
          <ode>
            <mu>10000</mu>
            <mu2>10000</mu2>
          </ode>
        </friction>
        <contact>
          <ode>
            <kp>300000.0</kp>
            <kd>10000.0</kd>
          </ode>
        </contact>
      </surface>
    </collision>
    <inertial>
      <mass value="0.05"/>
      <inertia ixx="0.000025" ixy="0" ixz="0" iyy="0.000025" iyz="0" izz="0.000025"/>
    </inertial>
  </link>
  <joint name="jtoe3" type="fixed">
    <parent link="lower3"/>
    <child link="toe3"/>
    <origin xyz="0.33643 0 -0.00628"/>
    <dynamics damping="0.0" friction="0.0"/>
  </joint>
  <link name="front_sensor_head_link"/>
  <link name="t265_rot_link"/>
  <joint name="fsh_frame_to_fisheye_center" type="fixed">
    <parent link="front_sensor_head_link"/>
    <child link="t265_rot_link"/>
    <origin rpy="0 0 0" xyz="0.03655 0.0 0.014"/>
    <axis xyz="1 0 0"/>
  </joint>
  <link name="t265_fisheye1_frame"/>
  <joint name="t265_pose_frame_to_t265_rot" type="fixed">
    <child link="t265_pose_frame"/>
    <parent link="t265_rot_link"/>
    <origin rpy="1.57 0 0" xyz="0 0 0"/>
    <axis xyz="1 0 0"/>
  </joint>
  <link name="t265_pose_frame"/>
  <joint name="t265_fisheye1_frame_to_center" type="fixed">
    <parent link="t265_pose_frame"/>
    <child link="t265_fisheye1_frame"/>
    <origin rpy="0 0 0" xyz="0.0 0.032 0.0"/>
    <axis xyz="1 0 0"/>
  </joint>
  <!-- begin branch 2 from t265_fisheye1_frame -->
  <!-- connect to the rest of the sensors -->
  <link name="t265_fisheye1_optical_frame"/>
  <joint name="t265_left_frame_to_t265_left_optical" type="fixed">
    <parent link="t265_fisheye1_frame"/>
    <child link="t265_fisheye1_optical_frame"/>
    <origin rpy="-1.571 0 -1.571" xyz="0.0 0.0 0.0"/>
    <axis xyz="1 0 0 "/>
  </joint>
  <!-- Left PMD -->
  <link name="left_tof_optical_parent_frame"/>
  <joint name="t265_left_optical_link_to_left_tof_optical_frame" type="fixed">
    <parent link="t265_fisheye1_optical_frame"/>
    <child link="left_tof_optical_parent_frame"/>
    <origin rpy="0.3961 0.4984 0.1937" xyz="0.0129 0.0225 -0.0088"/>
    <axis xyz="0 0 1"/>
  </joint>
  <link name="left_tof_link"/>
  <joint name="left_tof_parent_to_sensor" type="fixed">
    <parent link="left_tof_optical_parent_frame"/>
    <child link="left_tof_link"/>
    <origin rpy="1.5708 -1.5708 0 " xyz="0 0 0"/>
    <axis xyz="1 0 0"/>
  </joint>
  <!-- Right PMD -->
  <link name="right_tof_optical_parent_frame"/>
  <joint name="left_tof_optical_frame_to_right_tof_optical_frame" type="fixed">
    <parent link="left_tof_optical_parent_frame"/>
    <child link="right_tof_optical_parent_frame"/>
    <origin rpy="-0.5896 -0.0931 -0.3423" xyz="-0.0084 -0.0420 0.0126"/>
    <axis xyz="0 0 1"/>
  </joint>
  <link name="right_tof_link"/>
  <joint name="right_tof_parent_to_sensor" type="fixed">
    <parent link="right_tof_optical_parent_frame"/>
    <child link="right_tof_link"/>
    <origin rpy="1.5708 -1.5708 0" xyz="0 0 0"/>
    <axis xyz="1 0 0"/>
  </joint>
  <!-- Rigid transform between low level "body" and high "level" body-->
  <joint name="body_to_front_sensor_head" type="fixed">
    <parent link="body"/>
    <child link="front_sensor_head_link"/>
    <origin xyz="0.425 0 0"/>
    <axis xyz="1 0 0"/>
  </joint>
  <!-- fake offset needed for planner DO NOT CHANGE -->
  <link name="body_planner"/>
  <joint name="body_to_planner_body" type="fixed">
    <parent link="body"/>
    <child link="body_planner"/>
    <origin xyz="0.015 0 -0.04"/>
    <axis xyz="1 0 0"/>
  </joint>
  <link name="imu_link"/>
  <joint name="body_to_imu_link" type="fixed">
    <parent link="body"/>
    <child link="imu_link"/>
    <origin rpy="0 0 0" xyz="0.00584 0.00812 0.012605"/>
    <axis xyz="1 0 0"/>
  </joint>
  <link name="imu_raw_link"/>
  <joint name="body_to_imu_raw_link" type="fixed">
    <parent link="body"/>
    <child link="imu_raw_link"/>
    <origin rpy="3.141593 0 1.570796" xyz="0.00584 0.00812 0.012605"/>
    <axis xyz="1 0 0"/>
  </joint>
  <link name="os1_sensor"/>
  <joint name="body_to_os1_sensor" type="fixed">
    <parent link="body"/>
    <child link="os1_sensor"/>
    <origin rpy="0 0 0" xyz="0.4372 0 0"/>
    <axis xyz="1 0 0"/>
  </joint>
  <link name="s_right_tof_link"/>
  <joint name="body_to_s_right_tof" type="fixed">
    <parent link="body"/>
    <child link="s_right_tof_link"/>
    <origin rpy="3.1415 0.524 -1.57" xyz="-0.082 -0.119 0.061"/>
    <axis xyz="1 0 0"/>
  </joint>
  <link name="s_left_tof_link"/>
  <joint name="body_to_s_left_tof" type="fixed">
    <parent link="body"/>
    <child link="s_left_tof_link"/>
    <origin rpy="0 0.524 1.57" xyz="-0.082 0.119 0.061"/>
    <axis xyz="1 0 0"/>
  </joint>
  <!--    Rear_tof    -->
  <link name="rear_tof_link"/>
  <joint name="body_to_rear_tof" type="fixed">
    <parent link="body"/>
    <child link="rear_tof_link"/>
    <origin rpy="0.0 0.55 3.14" xyz="-0.43687 -0.01875 0.04171"/>
    <axis xyz="1 0 0"/>
  </joint>
  <!-- Fake front depth camera -->
  <link name="synth_depth_left_camera_frame"/>
  <joint name="synth_depth_left_camera_joint" type="fixed">
    <parent link="front_sensor_head_link"/>
    <child link="synth_depth_left_camera_frame"/>
    <origin rpy="0 0.25 0" xyz="0 0 -0.15"/>
    <axis xyz="0 1 0"/>
  </joint>
  <link name="synth_depth_left_camera_optical_frame"/>
  <joint name="synth_depth_left_camera_optical_frame" type="fixed">
    <origin rpy="-1.57079632679 0.0 -1.57079632679" xyz="0 0 0"/>
    <parent link="synth_depth_left_camera_frame"/>
    <child link="synth_depth_left_camera_optical_frame"/>
  </joint>
  <!-- Frame corners -->
  <!-- Top corners -->
  <!--
   <link name="flt_corner_link"/>
    <joint name="body_to_flt_corner_link" type="fixed">
        <parent link="body"/>
        <child link="flt_corner_link"/>
       <origin xyz="0.425  0.115 0.09" rpy="0.0 0.0 0.0"/>
        <axis xyz="1 0 0"/>
    </joint>


    <link name="frt_corner_link"/>
    <joint name="body_to_frt_corner_link" type="fixed">
        <parent link="body"/>
        <child link="frt_corner_link"/>
       <origin xyz="0.425  -0.115 0.09" rpy="0.0 0.0 0.0"/>
        <axis xyz="1 0 0"/>
    </joint>
    
    <link name="brt_corner_link"/>
    <joint name="body_to_brt_corner_link" type="fixed">
        <parent link="body"/>
        <child link="brt_corner_link"/>
       <origin xyz="-0.425  -0.115 0.09" rpy="0.0 0.0 0.0"/>
        <axis xyz="1 0 0"/>
    </joint>


    <link name="blt_corner_link"/>
    <joint name="body_to_blt_corner_link" type="fixed">
        <parent link="body"/>
        <child link="blt_corner_link"/>
       <origin xyz="-0.425  0.115 0.09" rpy="0.0 0.0 0.0"/>
        <axis xyz="1 0 0"/>
    </joint>
-->
  <!-- bottom corners-->
  <!--
    <link name="flb_corner_link"/>
    <joint name="body_to_flb_corner_link" type="fixed">
        <parent link="body"/>
        <child link="flb_corner_link"/>
       <origin xyz="0.425  0.115 -0.09" rpy="0.0 0.0 0.0"/>
        <axis xyz="1 0 0"/>
    </joint>


    <link name="frb_corner_link"/>
    <joint name="body_to_frb_corner_link" type="fixed">
        <parent link="body"/>
        <child link="frb_corner_link"/>
       <origin xyz="0.425  -0.115 -0.09" rpy="0.0 0.0 0.0"/>
        <axis xyz="1 0 0"/>
    </joint>

    <link name="brb_corner_link"/>
    <joint name="body_to_brb_corner_link" type="fixed">
        <parent link="body"/>
        <child link="brb_corner_link"/>
       <origin xyz="-0.425  -0.115 -0.09" rpy="0.0 0.0 0.0"/>
        <axis xyz="1 0 0"/>
    </joint>

    <link name="blb_corner_link"/>
    <joint name="body_to_blb_corner_link" type="fixed">
        <parent link="body"/>
        <child link="blb_corner_link"/>
       <origin xyz="-0.425  0.115 -0.09" rpy="0.0 0.0 0.0"/>
        <axis xyz="1 0 0"/>
    </joint>
-->
</robot>

