<sdf version='1.6'>
  <model name='ngr'>
    <link name='body'>
      <pose frame=''>0 0 0 0 -0 0</pose>
      <inertial>
        <pose frame=''>0 0 0 0 -0 0</pose>
        <mass>17.9</mass>
        <inertia>
          <ixx>0.0986</ixx>
          <ixy>0</ixy>
          <ixz>0</ixz>
          <iyy>0.8105</iyy>
          <iyz>0</iyz>
          <izz>0.8369</izz>
        </inertia>
      </inertial>
      <collision name='body_collision'>
        <pose frame=''>0 0 0 0 -0 0</pose>
        <geometry>
          <box>
            <size>0.83 0.25 0.19</size>
          </box>
        </geometry>
        <surface>
          <contact>
            <ode/>
          </contact>
          <friction>
            <ode/>
          </friction>
        </surface>
      </collision>
      <visual name='body_visual'>
        <pose frame=''>0 0 0 0 -0 0</pose>
        <geometry>
          <box>
            <size>0.83 0.25 0.19</size>
          </box>
        </geometry>
        <material>
          <script>
            <name>Gazebo/BlackTransparent</name>
            <uri>file://media/materials/scripts/gazebo.material</uri>
          </script>
        </material>
      </visual>
      <velocity_decay/>
      <velocity_decay/>
      <sensor name='imu_sensor' type='imu'>
        <always_on>1</always_on>
        <update_rate>500</update_rate>
        <visualize>1</visualize>
        <topic>__default_topic_</topic>
        <plugin name='imu_plugin' filename='libgazebo_ros_imu_sensor.so'>
          <topicName>imu</topicName>
          <bodyName>body</bodyName>
          <updateRateHZ>500.0</updateRateHZ>
          <gaussianNoise>0.0</gaussianNoise>
          <xyzOffset>0 0 0</xyzOffset>
          <rpyOffset>0 0 0</rpyOffset>
          <frameName>body</frameName>
          <initialOrientationAsReference>1</initialOrientationAsReference>
        </plugin>
        <pose frame=''>0 0 0 0 -0 0</pose>
      </sensor>
      <velocity_decay/>
      <sensor name='left_tof' type='depth'>
        <update_rate>15</update_rate>
        <camera name='__default__'>
          <horizontal_fov>1.08</horizontal_fov>
          <image>
            <width>171</width>
            <height>224</height>
            <format>R8G8B8</format>
          </image>
          <clip>
            <near>0.05</near>
            <far>2.5</far>
          </clip>
        </camera>
        <plugin name='left_tof_controller' filename='libgazebo_ros_openni_kinect.so'>
          <baseline>0.2</baseline>
          <alwaysOn>1</alwaysOn>
          <updateRate>0</updateRate>
          <cameraName>left_tof</cameraName>
          <imageTopicName>/left_tof/stream/1/color/image_rect_raw</imageTopicName>
          <cameraInfoTopicName>/left_tof/stream/1/color/camera_info</cameraInfoTopicName>
          <depthImageTopicName>/left_tof/stream/1/depth/image_rect_raw</depthImageTopicName>
          <depthImageCameraInfoTopicName>/left_tof/stream/1/depth/camera_info</depthImageCameraInfoTopicName>
          <pointCloudTopicName>/left_tof/stream/1/cloud</pointCloudTopicName>
          <frameName>left_tof_optical_link</frameName>
          <pointCloudCutoff>0.1</pointCloudCutoff>
          <pointCloudCutoffMax>2.5</pointCloudCutoffMax>
          <distortionK1>0.00000001</distortionK1>
          <distortionK2>0.00000001</distortionK2>
          <distortionK3>0.00000001</distortionK3>
          <distortionT1>0.00000001</distortionT1>
          <distortionT2>0.00000001</distortionT2>
          <CxPrime>0</CxPrime>
          <Cx>0</Cx>
          <Cy>0</Cy>
          <focalLength>0</focalLength>
          <hackBaseline>0</hackBaseline>
        </plugin>
        <pose frame=''>0.49993 0.033445 -0.00212 -0 0.5235 -0.349</pose>
      </sensor>
      <gravity>1</gravity>
      <velocity_decay/>
      <sensor name='front_depth' type='depth'>
        <update_rate>30</update_rate>
        <camera name='__default__'>
          <horizontal_fov>1.2</horizontal_fov>
          <image>
            <width>640</width>
            <height>480</height>
            <format>R8G8B8</format>
          </image>
          <clip>
            <near>0.05</near>
            <far>4</far>
          </clip>
        </camera>
        <plugin name='front_depth_controller' filename='libgazebo_ros_openni_kinect.so'>
          <baseline>0.2</baseline>
          <alwaysOn>1</alwaysOn>
          <updateRate>0</updateRate>
          <cameraName>d435i</cameraName>
          <imageTopicName>/d435i/color/image_raw</imageTopicName>
          <cameraInfoTopicName>/d435i/color/camera_info</cameraInfoTopicName>
          <depthImageTopicName>/d435i/depth/image_rect_raw</depthImageTopicName>
          <depthImageCameraInfoTopicName>/d435i/depth/camera_info</depthImageCameraInfoTopicName>
          <pointCloudTopicName>/d435i/depth/points</pointCloudTopicName>
          <frameName>d435i_optical_link</frameName>
          <pointCloudCutoff>0.5</pointCloudCutoff>
          <pointCloudCutoffMax>3.0</pointCloudCutoffMax>
          <distortionK1>0.00000001</distortionK1>
          <distortionK2>0.00000001</distortionK2>
          <distortionK3>0.00000001</distortionK3>
          <distortionT1>0.00000001</distortionT1>
          <distortionT2>0.00000001</distortionT2>
          <CxPrime>0</CxPrime>
          <Cx>319.06939697265625</Cx>
          <Cy>241.25682067871094</Cy>
          <focalLength>0</focalLength>
          <hackBaseline>0</hackBaseline>
        </plugin>
        <pose frame=''>0.454 0 0.0456 0 -0 0</pose>
      </sensor>
      <gravity>1</gravity>
      <velocity_decay/>
      <sensor name='right_tof' type='depth'>
        <update_rate>15</update_rate>
        <camera name='__default__'>
          <horizontal_fov>1.08</horizontal_fov>
          <image>
            <width>171</width>
            <height>224</height>
            <format>R8G8B8</format>
          </image>
          <clip>
            <near>0.05</near>
            <far>2.5</far>
          </clip>
        </camera>
        <plugin name='right_tof_controller' filename='libgazebo_ros_openni_kinect.so'>
          <baseline>0.2</baseline>
          <alwaysOn>1</alwaysOn>
          <updateRate>0</updateRate>
          <cameraName>right_tof</cameraName>
          <imageTopicName>/right_tof/stream/1/color/image_rect_raw</imageTopicName>
          <cameraInfoTopicName>/right_tof/stream/1/color/camera_info</cameraInfoTopicName>
          <depthImageTopicName>/right_tof/stream/1/depth/image_rect_raw</depthImageTopicName>
          <depthImageCameraInfoTopicName>/right_tof/depth/camera_info</depthImageCameraInfoTopicName>
          <pointCloudTopicName>/right_tof/stream/1/cloud</pointCloudTopicName>
          <frameName>right_tof_link</frameName>
          <pointCloudCutoff>0.1</pointCloudCutoff>
          <pointCloudCutoffMax>2.5</pointCloudCutoffMax>
          <distortionK1>0.00000001</distortionK1>
          <distortionK2>0.00000001</distortionK2>
          <distortionK3>0.00000001</distortionK3>
          <distortionT1>0.00000001</distortionT1>
          <distortionT2>0.00000001</distortionT2>
          <CxPrime>0</CxPrime>
          <Cx>0</Cx>
          <Cy>0</Cy>
          <focalLength>0</focalLength>
          <hackBaseline>0</hackBaseline>
        </plugin>
        <pose frame=''>0.49993 -0.033445 -0.00212 0 0.5235 0.349</pose>
      </sensor>
    </link>
    <link name='hip2'>
      <pose frame=''>0.34385 -0.092865 0 0 -0 0</pose>
      <inertial>
        <pose frame=''>0 0 0 0 -0 0</pose>
        <mass>1.975</mass>
        <inertia>
          <ixx>0.00891458</ixx>
          <ixy>0</ixy>
          <ixz>0</ixz>
          <iyy>0.0100573</iyy>
          <iyz>0</iyz>
          <izz>0.015337</izz>
        </inertia>
      </inertial>
      <collision name='hip2_collision'>
        <pose frame=''>-0.01 0.005 0 1.5708 -0 0</pose>
        <geometry>
          <box>
            <size>0.15 0.09 0.15</size>
          </box>
        </geometry>
        <surface>
          <contact>
            <ode/>
          </contact>
          <friction>
            <ode/>
          </friction>
        </surface>
      </collision>
      <visual name='hip2_visual'>
        <pose frame=''>-0.01 0.005 0 1.5708 -0 0</pose>
        <geometry>
          <box>
            <size>0.15 0.09 0.15</size>
          </box>
        </geometry>
        <material>
          <script>
            <name>Gazebo/Purple</name>
            <uri>file://media/materials/scripts/gazebo.material</uri>
          </script>
        </material>
      </visual>
      <gravity>1</gravity>
      <velocity_decay/>
    </link>
    <joint name='10' type='revolute'>
      <child>hip2</child>
      <parent>body</parent>
      <axis>
        <xyz>1 0 0</xyz>
        <limit>
          <lower>-0.43</lower>
          <upper>0.43</upper>
          <effort>375</effort>
          <velocity>8.6</velocity>
        </limit>
        <dynamics>
          <damping>0</damping>
          <friction>0</friction>
          <spring_reference>0</spring_reference>
          <spring_stiffness>0</spring_stiffness>
        </dynamics>
        <use_parent_model_frame>1</use_parent_model_frame>
      </axis>
    </joint>
    <link name='upper2'>
      <pose frame=''>0.34385 -0.190365 0 0 -0 0</pose>
      <inertial>
        <pose frame=''>0 0 0 0 -0 0</pose>
        <mass>2.525</mass>
        <inertia>
          <ixx>0.0003125</ixx>
          <ixy>0</ixy>
          <ixz>0</ixz>
          <iyy>0.0040625</iyy>
          <iyz>0</iyz>
          <izz>0.0040625</izz>
        </inertia>
      </inertial>
      <collision name='upper2_collision'>
        <pose frame=''>-0.17 -0 0 0 -0 0</pose>
        <geometry>
          <box>
            <size>0.34 0.055 0.075</size>
          </box>
        </geometry>
        <surface>
          <contact>
            <ode/>
          </contact>
          <friction>
            <ode/>
          </friction>
        </surface>
      </collision>
      <visual name='upper2_visual'>
        <pose frame=''>-0.17 -0 0 0 -0 0</pose>
        <geometry>
          <box>
            <size>0.34 0.055 0.075</size>
          </box>
        </geometry>
        <material>
          <script>
            <name>Gazebo/Blue</name>
            <uri>file://media/materials/scripts/gazebo.material</uri>
          </script>
        </material>
      </visual>
      <gravity>1</gravity>
      <velocity_decay/>
    </link>
    <joint name='4' type='revolute'>
      <child>upper2</child>
      <parent>hip2</parent>
      <axis>
        <xyz>0 -1 0</xyz>
        <limit>
          <lower>-6.28319</lower>
          <upper>6.28319</upper>
          <effort>87.5</effort>
          <velocity>30</velocity>
        </limit>
        <dynamics>
          <damping>0</damping>
          <friction>0</friction>
          <spring_reference>0</spring_reference>
          <spring_stiffness>0</spring_stiffness>
        </dynamics>
        <use_parent_model_frame>1</use_parent_model_frame>
      </axis>
    </joint>
    <link name='lower2'>
      <pose frame=''>0.00385 -0.190365 0 0 -0 0</pose>
      <inertial>
        <pose frame=''>0.097343 0 0 0 -0 0</pose>
        <mass>0.525</mass>
        <inertia>
          <ixx>0.00133575</ixx>
          <ixy>0</ixy>
          <ixz>0</ixz>
          <iyy>0.0137725</iyy>
          <iyz>0</iyz>
          <izz>0.0125618</izz>
        </inertia>
      </inertial>
      <collision name='lower2_collision'>
        <pose frame=''>0.17035 0 0 3.14159 1.57079 3.14159</pose>
        <geometry>
          <cylinder>
            <length>0.3407</length>
            <radius>0.02</radius>
          </cylinder>
        </geometry>
        <surface>
          <contact>
            <ode/>
          </contact>
          <friction>
            <ode/>
          </friction>
        </surface>
      </collision>
      <collision name='lower2_fixed_joint_lump__toe2_collision_1'>
        <pose frame=''>0.3407 0 0 0 -0 0</pose>
        <geometry>
          <sphere>
            <radius>0.0325</radius>
          </sphere>
        </geometry>
        <surface>
          <bounce>
            <restitution_coefficient>0</restitution_coefficient>
            <threshold>1e+06</threshold>
          </bounce>
          <friction>
            <torsional>
              <coefficient>0.3</coefficient>
            </torsional>
            <ode>
              <mu>20</mu>
              <mu2>10</mu2>
            </ode>
            <bullet>
              <rolling_friction>0.3</rolling_friction>
              <friction2>10</friction2>
            </bullet>
          </friction>
          <contact>
            <bullet>
              <kp>30000</kp>
              <kd>1000</kd>
              <split_impulse>1</split_impulse>
              <split_impulse_penetration_threshold>-0.01</split_impulse_penetration_threshold>
            </bullet>
            <ode>
              <kp>30000</kp>
              <kd>1000</kd>
            </ode>
          </contact>
        </surface>
      </collision>
      <visual name='lower2_visual'>
        <pose frame=''>0.17035 0 0 3.14159 1.57079 3.14159</pose>
        <geometry>
          <cylinder>
            <length>0.3407</length>
            <radius>0.02</radius>
          </cylinder>
        </geometry>
        <material>
          <script>
            <name>Gazebo/Black</name>
            <uri>file://media/materials/scripts/gazebo.material</uri>
          </script>
        </material>
      </visual>
      <visual name='lower2_fixed_joint_lump__toe2_visual_1'>
        <pose frame=''>0.3407 0 0 0 -0 0</pose>
        <geometry>
          <sphere>
            <radius>0.0325</radius>
          </sphere>
        </geometry>
        <material>
          <script>
            <name>Gazebo/DarkGray</name>
            <uri>file://media/materials/scripts/gazebo.material</uri>
          </script>
        </material>
      </visual>
      <velocity_decay/>
      <gravity>1</gravity>
      <velocity_decay/>
    </link>
    <joint name='5' type='revolute'>
      <child>lower2</child>
      <parent>upper2</parent>
      <axis>
        <xyz>0 1 0</xyz>
        <limit>
          <lower>0</lower>
          <upper>3.14159</upper>
          <effort>87.5</effort>
          <velocity>30</velocity>
        </limit>
        <dynamics>
          <damping>0</damping>
          <friction>0</friction>
          <spring_reference>0</spring_reference>
          <spring_stiffness>0</spring_stiffness>
        </dynamics>
        <use_parent_model_frame>1</use_parent_model_frame>
      </axis>
    </joint>
    <link name='hip3'>
      <pose frame=''>-0.34385 -0.092865 0 0 -0 0</pose>
      <inertial>
        <pose frame=''>0 0 0 0 -0 0</pose>
        <mass>1.975</mass>
        <inertia>
          <ixx>0.00891458</ixx>
          <ixy>0</ixy>
          <ixz>0</ixz>
          <iyy>0.0100573</iyy>
          <iyz>0</iyz>
          <izz>0.015337</izz>
        </inertia>
      </inertial>
      <collision name='hip3_collision'>
        <pose frame=''>0.01 0.005 0 1.5708 -0 0</pose>
        <geometry>
          <box>
            <size>0.15 0.09 0.15</size>
          </box>
        </geometry>
        <surface>
          <contact>
            <ode/>
          </contact>
          <friction>
            <ode/>
          </friction>
        </surface>
      </collision>
      <visual name='hip3_visual'>
        <pose frame=''>0.01 0.005 0 1.5708 -0 0</pose>
        <geometry>
          <box>
            <size>0.15 0.09 0.15</size>
          </box>
        </geometry>
        <material>
          <script>
            <name>Gazebo/Purple</name>
            <uri>file://media/materials/scripts/gazebo.material</uri>
          </script>
        </material>
      </visual>
      <gravity>1</gravity>
      <velocity_decay/>
    </link>
    <joint name='11' type='revolute'>
      <child>hip3</child>
      <parent>body</parent>
      <axis>
        <xyz>1 0 0</xyz>
        <limit>
          <lower>-0.43</lower>
          <upper>0.43</upper>
          <effort>375</effort>
          <velocity>8.6</velocity>
        </limit>
        <dynamics>
          <damping>0</damping>
          <friction>0</friction>
          <spring_reference>0</spring_reference>
          <spring_stiffness>0</spring_stiffness>
        </dynamics>
        <use_parent_model_frame>1</use_parent_model_frame>
      </axis>
    </joint>
    <link name='upper3'>
      <pose frame=''>-0.34385 -0.190365 0 0 -0 0</pose>
      <inertial>
        <pose frame=''>0 0 0 0 -0 0</pose>
        <mass>2.525</mass>
        <inertia>
          <ixx>0.0003125</ixx>
          <ixy>0</ixy>
          <ixz>0</ixz>
          <iyy>0.0040625</iyy>
          <iyz>0</iyz>
          <izz>0.0040625</izz>
        </inertia>
      </inertial>
      <collision name='upper3_collision'>
        <pose frame=''>-0.17 -0 0 0 -0 0</pose>
        <geometry>
          <box>
            <size>0.34 0.055 0.075</size>
          </box>
        </geometry>
        <surface>
          <contact>
            <ode/>
          </contact>
          <friction>
            <ode/>
          </friction>
        </surface>
      </collision>
      <visual name='upper3_visual'>
        <pose frame=''>-0.17 -0 0 0 -0 0</pose>
        <geometry>
          <box>
            <size>0.34 0.055 0.075</size>
          </box>
        </geometry>
        <material>
          <script>
            <name>Gazebo/Blue</name>
            <uri>file://media/materials/scripts/gazebo.material</uri>
          </script>
        </material>
      </visual>
      <gravity>1</gravity>
      <velocity_decay/>
    </link>
    <joint name='6' type='revolute'>
      <child>upper3</child>
      <parent>hip3</parent>
      <axis>
        <xyz>0 -1 0</xyz>
        <limit>
          <lower>-6.28319</lower>
          <upper>6.28319</upper>
          <effort>87.5</effort>
          <velocity>30</velocity>
        </limit>
        <dynamics>
          <damping>0</damping>
          <friction>0</friction>
          <spring_reference>0</spring_reference>
          <spring_stiffness>0</spring_stiffness>
        </dynamics>
        <use_parent_model_frame>1</use_parent_model_frame>
      </axis>
    </joint>
    <link name='lower3'>
      <pose frame=''>-0.68385 -0.190365 0 0 -0 0</pose>
      <inertial>
        <pose frame=''>0.097343 0 0 0 -0 0</pose>
        <mass>0.525</mass>
        <inertia>
          <ixx>0.00133575</ixx>
          <ixy>0</ixy>
          <ixz>0</ixz>
          <iyy>0.0137725</iyy>
          <iyz>0</iyz>
          <izz>0.0125618</izz>
        </inertia>
      </inertial>
      <collision name='lower3_collision'>
        <pose frame=''>0.17035 0 0 3.14159 1.57079 3.14159</pose>
        <geometry>
          <cylinder>
            <length>0.3407</length>
            <radius>0.02</radius>
          </cylinder>
        </geometry>
        <surface>
          <contact>
            <ode/>
          </contact>
          <friction>
            <ode/>
          </friction>
        </surface>
      </collision>
      <collision name='lower3_fixed_joint_lump__toe3_collision_1'>
        <pose frame=''>0.3407 0 0 0 -0 0</pose>
        <geometry>
          <sphere>
            <radius>0.0325</radius>
          </sphere>
        </geometry>
        <surface>
          <bounce>
            <restitution_coefficient>0</restitution_coefficient>
            <threshold>1e+06</threshold>
          </bounce>
          <friction>
            <torsional>
              <coefficient>0.3</coefficient>
            </torsional>
            <ode>
              <mu>20</mu>
              <mu2>10</mu2>
            </ode>
            <bullet>
              <rolling_friction>0.3</rolling_friction>
              <friction2>10</friction2>
            </bullet>
          </friction>
          <contact>
            <bullet>
              <kp>30000</kp>
              <kd>1000</kd>
              <split_impulse>1</split_impulse>
              <split_impulse_penetration_threshold>-0.01</split_impulse_penetration_threshold>
            </bullet>
            <ode>
              <kp>30000</kp>
              <kd>1000</kd>
            </ode>
          </contact>
        </surface>
      </collision>
      <visual name='lower3_visual'>
        <pose frame=''>0.17035 0 0 3.14159 1.57079 3.14159</pose>
        <geometry>
          <cylinder>
            <length>0.3407</length>
            <radius>0.02</radius>
          </cylinder>
        </geometry>
        <material>
          <script>
            <name>Gazebo/Black</name>
            <uri>file://media/materials/scripts/gazebo.material</uri>
          </script>
        </material>
      </visual>
      <visual name='lower3_fixed_joint_lump__toe3_visual_1'>
        <pose frame=''>0.3407 0 0 0 -0 0</pose>
        <geometry>
          <sphere>
            <radius>0.0325</radius>
          </sphere>
        </geometry>
        <material>
          <script>
            <name>Gazebo/DarkGray</name>
            <uri>file://media/materials/scripts/gazebo.material</uri>
          </script>
        </material>
      </visual>
      <velocity_decay/>
      <gravity>1</gravity>
      <velocity_decay/>
    </link>
    <joint name='7' type='revolute'>
      <child>lower3</child>
      <parent>upper3</parent>
      <axis>
        <xyz>0 1 0</xyz>
        <limit>
          <lower>0</lower>
          <upper>3.14159</upper>
          <effort>87.5</effort>
          <velocity>30</velocity>
        </limit>
        <dynamics>
          <damping>0</damping>
          <friction>0</friction>
          <spring_reference>0</spring_reference>
          <spring_stiffness>0</spring_stiffness>
        </dynamics>
        <use_parent_model_frame>1</use_parent_model_frame>
      </axis>
    </joint>
    <link name='hip0'>
      <pose frame=''>0.34385 0.092865 0 0 -0 0</pose>
      <inertial>
        <pose frame=''>0 0 0 0 -0 0</pose>
        <mass>1.975</mass>
        <inertia>
          <ixx>0.00891458</ixx>
          <ixy>0</ixy>
          <ixz>0</ixz>
          <iyy>0.0100573</iyy>
          <iyz>0</iyz>
          <izz>0.015337</izz>
        </inertia>
      </inertial>
      <collision name='hip0_collision'>
        <pose frame=''>-0.01 -0.005 0 1.5708 -0 0</pose>
        <geometry>
          <box>
            <size>0.15 0.09 0.15</size>
          </box>
        </geometry>
        <surface>
          <contact>
            <ode/>
          </contact>
          <friction>
            <ode/>
          </friction>
        </surface>
      </collision>
      <visual name='hip0_visual'>
        <pose frame=''>-0.01 -0.005 0 1.5708 -0 0</pose>
        <geometry>
          <box>
            <size>0.15 0.09 0.15</size>
          </box>
        </geometry>
        <material>
          <script>
            <name>Gazebo/Purple</name>
            <uri>file://media/materials/scripts/gazebo.material</uri>
          </script>
        </material>
      </visual>
      <gravity>1</gravity>
      <velocity_decay/>
    </link>
    <joint name='8' type='revolute'>
      <child>hip0</child>
      <parent>body</parent>
      <axis>
        <xyz>1 0 0</xyz>
        <limit>
          <lower>-0.43</lower>
          <upper>0.43</upper>
          <effort>375</effort>
          <velocity>8.6</velocity>
        </limit>
        <dynamics>
          <damping>0</damping>
          <friction>0</friction>
          <spring_reference>0</spring_reference>
          <spring_stiffness>0</spring_stiffness>
        </dynamics>
        <use_parent_model_frame>1</use_parent_model_frame>
      </axis>
    </joint>
    <link name='upper0'>
      <pose frame=''>0.34385 0.190365 0 0 -0 0</pose>
      <inertial>
        <pose frame=''>0 0 0 0 -0 0</pose>
        <mass>2.525</mass>
        <inertia>
          <ixx>0.0003125</ixx>
          <ixy>0</ixy>
          <ixz>0</ixz>
          <iyy>0.0040625</iyy>
          <iyz>0</iyz>
          <izz>0.0040625</izz>
        </inertia>
      </inertial>
      <collision name='upper0_collision'>
        <pose frame=''>-0.17 0 0 0 -0 0</pose>
        <geometry>
          <box>
            <size>0.34 0.055 0.075</size>
          </box>
        </geometry>
        <surface>
          <contact>
            <ode/>
          </contact>
          <friction>
            <ode/>
          </friction>
        </surface>
      </collision>
      <visual name='upper0_visual'>
        <pose frame=''>-0.17 0 0 0 -0 0</pose>
        <geometry>
          <box>
            <size>0.34 0.055 0.075</size>
          </box>
        </geometry>
        <material>
          <script>
            <name>Gazebo/Blue</name>
            <uri>file://media/materials/scripts/gazebo.material</uri>
          </script>
        </material>
      </visual>
      <gravity>1</gravity>
      <velocity_decay/>
    </link>
    <joint name='0' type='revolute'>
      <child>upper0</child>
      <parent>hip0</parent>
      <axis>
        <xyz>0 -1 0</xyz>
        <limit>
          <lower>-6.28319</lower>
          <upper>6.28319</upper>
          <effort>87.5</effort>
          <velocity>30</velocity>
        </limit>
        <dynamics>
          <damping>0</damping>
          <friction>0</friction>
          <spring_reference>0</spring_reference>
          <spring_stiffness>0</spring_stiffness>
        </dynamics>
        <use_parent_model_frame>1</use_parent_model_frame>
      </axis>
    </joint>
    <link name='lower0'>
      <pose frame=''>0.00385 0.190365 0 0 -0 0</pose>
      <inertial>
        <pose frame=''>0.097343 0 0 0 -0 0</pose>
        <mass>0.525</mass>
        <inertia>
          <ixx>0.00133575</ixx>
          <ixy>0</ixy>
          <ixz>0</ixz>
          <iyy>0.0137725</iyy>
          <iyz>0</iyz>
          <izz>0.0125618</izz>
        </inertia>
      </inertial>
      <collision name='lower0_collision'>
        <pose frame=''>0.17035 0 0 3.14159 1.57079 3.14159</pose>
        <geometry>
          <cylinder>
            <length>0.3407</length>
            <radius>0.02</radius>
          </cylinder>
        </geometry>
        <surface>
          <contact>
            <ode/>
          </contact>
          <friction>
            <ode/>
          </friction>
        </surface>
      </collision>
      <collision name='lower0_fixed_joint_lump__toe0_collision_1'>
        <pose frame=''>0.3407 0 0 0 -0 0</pose>
        <geometry>
          <sphere>
            <radius>0.0325</radius>
          </sphere>
        </geometry>
        <surface>
          <bounce>
            <restitution_coefficient>0</restitution_coefficient>
            <threshold>1e+06</threshold>
          </bounce>
          <friction>
            <torsional>
              <coefficient>0.3</coefficient>
            </torsional>
            <ode>
              <mu>20</mu>
              <mu2>10</mu2>
            </ode>
            <bullet>
              <rolling_friction>0.3</rolling_friction>
              <friction2>10</friction2>
            </bullet>
          </friction>
          <contact>
            <bullet>
              <kp>30000</kp>
              <kd>1000</kd>
              <split_impulse>1</split_impulse>
              <split_impulse_penetration_threshold>-0.01</split_impulse_penetration_threshold>
            </bullet>
            <ode>
              <kp>30000</kp>
              <kd>1000</kd>
            </ode>
          </contact>
        </surface>
      </collision>
      <visual name='lower0_visual'>
        <pose frame=''>0.17035 0 0 3.14159 1.57079 3.14159</pose>
        <geometry>
          <cylinder>
            <length>0.3407</length>
            <radius>0.02</radius>
          </cylinder>
        </geometry>
        <material>
          <script>
            <name>Gazebo/Black</name>
            <uri>file://media/materials/scripts/gazebo.material</uri>
          </script>
        </material>
      </visual>
      <visual name='lower0_fixed_joint_lump__toe0_visual_1'>
        <pose frame=''>0.3407 0 0 0 -0 0</pose>
        <geometry>
          <sphere>
            <radius>0.0325</radius>
          </sphere>
        </geometry>
        <material>
          <script>
            <name>Gazebo/DarkGray</name>
            <uri>file://media/materials/scripts/gazebo.material</uri>
          </script>
        </material>
      </visual>
      <velocity_decay/>
      <gravity>1</gravity>
      <velocity_decay/>
    </link>
    <joint name='1' type='revolute'>
      <child>lower0</child>
      <parent>upper0</parent>
      <axis>
        <xyz>0 1 0</xyz>
        <limit>
          <lower>0</lower>
          <upper>3.14159</upper>
          <effort>87.5</effort>
          <velocity>30</velocity>
        </limit>
        <dynamics>
          <damping>0</damping>
          <friction>0</friction>
          <spring_reference>0</spring_reference>
          <spring_stiffness>0</spring_stiffness>
        </dynamics>
        <use_parent_model_frame>1</use_parent_model_frame>
      </axis>
    </joint>
    <link name='hip1'>
      <pose frame=''>-0.34385 0.092865 0 0 -0 0</pose>
      <inertial>
        <pose frame=''>0 0 0 0 -0 0</pose>
        <mass>1.975</mass>
        <inertia>
          <ixx>0.00891458</ixx>
          <ixy>0</ixy>
          <ixz>0</ixz>
          <iyy>0.0100573</iyy>
          <iyz>0</iyz>
          <izz>0.015337</izz>
        </inertia>
      </inertial>
      <collision name='hip1_collision'>
        <pose frame=''>0.01 -0.005 0 1.5708 -0 0</pose>
        <geometry>
          <box>
            <size>0.15 0.09 0.15</size>
          </box>
        </geometry>
        <surface>
          <contact>
            <ode/>
          </contact>
          <friction>
            <ode/>
          </friction>
        </surface>
      </collision>
      <visual name='hip1_visual'>
        <pose frame=''>0.01 -0.005 0 1.5708 -0 0</pose>
        <geometry>
          <box>
            <size>0.15 0.09 0.15</size>
          </box>
        </geometry>
        <material>
          <script>
            <name>Gazebo/Purple</name>
            <uri>file://media/materials/scripts/gazebo.material</uri>
          </script>
        </material>
      </visual>
      <gravity>1</gravity>
      <velocity_decay/>
    </link>
    <joint name='9' type='revolute'>
      <child>hip1</child>
      <parent>body</parent>
      <axis>
        <xyz>1 0 0</xyz>
        <limit>
          <lower>-0.43</lower>
          <upper>0.43</upper>
          <effort>375</effort>
          <velocity>8.6</velocity>
        </limit>
        <dynamics>
          <damping>0</damping>
          <friction>0</friction>
          <spring_reference>0</spring_reference>
          <spring_stiffness>0</spring_stiffness>
        </dynamics>
        <use_parent_model_frame>1</use_parent_model_frame>
      </axis>
    </joint>
    <link name='upper1'>
      <pose frame=''>-0.34385 0.190365 0 0 -0 0</pose>
      <inertial>
        <pose frame=''>0 0 0 0 -0 0</pose>
        <mass>2.525</mass>
        <inertia>
          <ixx>0.0003125</ixx>
          <ixy>0</ixy>
          <ixz>0</ixz>
          <iyy>0.0040625</iyy>
          <iyz>0</iyz>
          <izz>0.0040625</izz>
        </inertia>
      </inertial>
      <collision name='upper1_collision'>
        <pose frame=''>-0.17 0 0 0 -0 0</pose>
        <geometry>
          <box>
            <size>0.34 0.055 0.075</size>
          </box>
        </geometry>
        <surface>
          <contact>
            <ode/>
          </contact>
          <friction>
            <ode/>
          </friction>
        </surface>
      </collision>
      <visual name='upper1_visual'>
        <pose frame=''>-0.17 0 0 0 -0 0</pose>
        <geometry>
          <box>
            <size>0.34 0.055 0.075</size>
          </box>
        </geometry>
        <material>
          <script>
            <name>Gazebo/Blue</name>
            <uri>file://media/materials/scripts/gazebo.material</uri>
          </script>
        </material>
      </visual>
      <gravity>1</gravity>
      <velocity_decay/>
    </link>
    <joint name='2' type='revolute'>
      <child>upper1</child>
      <parent>hip1</parent>
      <axis>
        <xyz>0 -1 0</xyz>
        <limit>
          <lower>-6.28319</lower>
          <upper>6.28319</upper>
          <effort>87.5</effort>
          <velocity>30</velocity>
        </limit>
        <dynamics>
          <damping>0</damping>
          <friction>0</friction>
          <spring_reference>0</spring_reference>
          <spring_stiffness>0</spring_stiffness>
        </dynamics>
        <use_parent_model_frame>1</use_parent_model_frame>
      </axis>
    </joint>
    <link name='lower1'>
      <pose frame=''>-0.68385 0.190365 0 0 -0 0</pose>
      <inertial>
        <pose frame=''>0.097343 0 0 0 -0 0</pose>
        <mass>0.525</mass>
        <inertia>
          <ixx>0.00133575</ixx>
          <ixy>0</ixy>
          <ixz>0</ixz>
          <iyy>0.0137725</iyy>
          <iyz>0</iyz>
          <izz>0.0125618</izz>
        </inertia>
      </inertial>
      <collision name='lower1_collision'>
        <pose frame=''>0.17035 0 0 3.14159 1.57079 3.14159</pose>
        <geometry>
          <cylinder>
            <length>0.3407</length>
            <radius>0.02</radius>
          </cylinder>
        </geometry>
        <surface>
          <contact>
            <ode/>
          </contact>
          <friction>
            <ode/>
          </friction>
        </surface>
      </collision>
      <collision name='lower1_fixed_joint_lump__toe1_collision_1'>
        <pose frame=''>0.3407 0 0 0 -0 0</pose>
        <geometry>
          <sphere>
            <radius>0.0325</radius>
          </sphere>
        </geometry>
        <surface>
          <bounce>
            <restitution_coefficient>0</restitution_coefficient>
            <threshold>1e+06</threshold>
          </bounce>
          <friction>
            <torsional>
              <coefficient>0.3</coefficient>
            </torsional>
            <ode>
              <mu>20</mu>
              <mu2>10</mu2>
            </ode>
            <bullet>
              <rolling_friction>0.3</rolling_friction>
              <friction2>10</friction2>
            </bullet>
          </friction>
          <contact>
            <bullet>
              <kp>30000</kp>
              <kd>1000</kd>
              <split_impulse>1</split_impulse>
              <split_impulse_penetration_threshold>-0.01</split_impulse_penetration_threshold>
            </bullet>
            <ode>
              <kp>30000</kp>
              <kd>1000</kd>
            </ode>
          </contact>
        </surface>
      </collision>
      <visual name='lower1_visual'>
        <pose frame=''>0.17035 0 0 3.14159 1.57079 3.14159</pose>
        <geometry>
          <cylinder>
            <length>0.3407</length>
            <radius>0.02</radius>
          </cylinder>
        </geometry>
        <material>
          <script>
            <name>Gazebo/Black</name>
            <uri>file://media/materials/scripts/gazebo.material</uri>
          </script>
        </material>
      </visual>
      <visual name='lower1_fixed_joint_lump__toe1_visual_1'>
        <pose frame=''>0.3407 0 0 0 -0 0</pose>
        <geometry>
          <sphere>
            <radius>0.0325</radius>
          </sphere>
        </geometry>
        <material>
          <script>
            <name>Gazebo/DarkGray</name>
            <uri>file://media/materials/scripts/gazebo.material</uri>
          </script>
        </material>
      </visual>
      <velocity_decay/>
      <gravity>1</gravity>
      <velocity_decay/>
    </link>
    <joint name='3' type='revolute'>
      <child>lower1</child>
      <parent>upper1</parent>
      <axis>
        <xyz>0 1 0</xyz>
        <limit>
          <lower>0</lower>
          <upper>3.14159</upper>
          <effort>87.5</effort>
          <velocity>30</velocity>
        </limit>
        <dynamics>
          <damping>0</damping>
          <friction>0</friction>
          <spring_reference>0</spring_reference>
          <spring_stiffness>0</spring_stiffness>
        </dynamics>
        <use_parent_model_frame>1</use_parent_model_frame>
      </axis>
    </joint>
    <plugin name='imu_plugin' filename='libgazebo_ros_imu.so'>
      <alwaysOn>1</alwaysOn>
      <bodyName>body</bodyName>
      <topicName>imu_other</topicName>
      <serviceName>imu_service</serviceName>
      <gaussianNoise>0.0</gaussianNoise>
      <updateRate>500.0</updateRate>
    </plugin>
    <static>0</static>
    <plugin name='gazebo_ros_control' filename='libgazebo_ros_control.so'>
      <robotNamespace>/vision60</robotNamespace>
    </plugin>
  </model>
</sdf>
